{
  "xsize": 16,
  "zsize": 16,
  "slices": [
    [
      "#$$#$$#$$#$$#$$#",
      "$##############$",
      "$##############$",
      "################",
      "$##############$",
      "$##############$",
      "################",
      "$##############$",
      "$##############$",
      "#######l########",
      "$##############$",
      "$##############$",
      "################",
      "$##############$",
      "$##############$",
      "#$$#$$#$$#$$#$$#"
    ],
    [
      "################",
      "#              #",
      "#   C          #",
      "#              #",
      "#              #",
      "#          C   #",
      "#              #",
      "#              #",
      "#  C           #",
      "#      l       #",
      "#     ###      #",
      "#           C  #",
      "#              #",
      "#     C        #",
      "#              #",
      "################"
    ],
    [
      "#aa#aa#aa#aa#aa#",
      "a              a",
      "a              a",
      "#              #",
      "a              a",
      "a              a",
      "#              #",
      "a              a",
      "a              a",
      "#      l       #",
      "a     ###      a",
      "a              a",
      "#              #",
      "a              a",
      "a              a",
      "#aa#aa#aa#aa#aa#"
    ],
    [
      "#aa#aa#aa#aa#aa#",
      "a              a",
      "a              a",
      "#              #",
      "a              a",
      "a              a",
      "#              #",
      "a              a",
      "a              a",
      "#      l       #",
      "a     ###      a",
      "a              a",
      "#              #",
      "a              a",
      "a              a",
      "#aa#aa#aa#aa#aa#"
    ],
    [
      "################",
      "################",
      "################",
      "################",
      "################",
      "################",
      "################",
      "################",
      "################",
      "#######l########",
      "################",
      "################",
      "################",
      "################",
      "################",
      "################"
    ],
    [
      "################",
      "################",
      "################",
      "################",
      "################",
      "################",
      "################",
      "################",
      "################",
      "#######l########",
      "################",
      "################",
      "################",
      "################",
      "################",
      "################"
    ]
  ]
}