{
  "xsize": 16,
  "zsize": 16,
  "slices": [
    [
      "#SSSSSSSSSSSSSS#",
      "S##############S",
      "S##############S",
      "S##############S",
      "S##############S",
      "S##############S",
      "S##############S",
      "S##############S",
      "S##############S",
      "S##############S",
      "S#########  ###S",
      "S#########  ###S",
      "S#########  ###S",
      "S#########cc###S",
      "S##############S",
      "#SSSSSSSSSSSSSS#"
    ],
    [
      "#aa#aa#aa#aa#aa#",
      "a  F  :        a",
      "a   C :        a",
      "#F T  #        #",
      "a     :    C   a",
      "a     :        a",
      "#::#  #        #",
      "a              a",
      "a  C      cc   a",
      "#     #  :dd:  #",
      "a     :  :  :  a",
      "a     :  :  :  a",
      "#     #  :  :  #",
      "a  C  :    C   a",
      "a     :        a",
      "#aa#aa#aa#aa#aa#"
    ],
    [
      "#aa#aa#aa#aa#aa#",
      "a     :        a",
      "a     :        a",
      "#     #        #",
      "a     :        a",
      "a     :        a",
      "#::#  #        #",
      "a              a",
      "a              a",
      "#     #   cc   #",
      "a     :   dd   a",
      "a     :        a",
      "#     #        #",
      "a     :        a",
      "a     :        a",
      "#aa#aa#aa#aa#aa#"
    ],
    [
      "#aa#aa#aa#aa#aa#",
      "a     :        a",
      "a     :        a",
      "#     #        #",
      "a     :        a",
      "a     :        a",
      "#::#  #        #",
      "a              a",
      "a              a",
      "#     #        #",
      "a     :   cc   a",
      "a     :   dd   a",
      "#     #        #",
      "a     :        a",
      "a     :        a",
      "#aa#aa#aa#aa#aa#"
    ],
    [
      "#SSSSSSSSSSSSSS#",
      "S##############S",
      "S##############S",
      "S##############S",
      "S##############S",
      "S##############S",
      "S##############S",
      "S##############S",
      "S#########  ###S",
      "S#########  ###S",
      "S#########  ###S",
      "S#########cc###S",
      "S##############S",
      "S##############S",
      "S##############S",
      "#SSSSSSSSSSSSSS#"
    ],
    [
      "################",
      "################",
      "################",
      "################",
      "################",
      "################",
      "################",
      "################",
      "################",
      "##########  ####",
      "##########  ####",
      "##########  ####",
      "##########cc####",
      "################",
      "################",
      "################"
    ]
  ]
}