{
  "xsize": 16,
  "zsize": 16,
  "slices": [
    [
      "################",
      "################",
      "################",
      "################",
      "################",
      "################",
      "################",
      "################",
      "################",
      "#######l########",
      "################",
      "################",
      "################",
      "################",
      "################",
      "################"
    ],
    [
      "#aa@aaaaaaaa@aa#",
      "aWWWWWWWWWWWWWWa",
      "aWWWWWWWWWWWWWWa",
      "@WWWWWWWWWWWWWW@",
      "aWWWWWWWWWWWWWWa",
      "aaaaaaaaaaaaaaaa",
      "a              a",
      "a  C           a",
      "aL          C  a",
      "a      l       a",
      "aF    ###::::::a",
      "a      :       a",
      "@  C   :   T   @",
      "a      :    C  a",
      "a      :       a",
      "#aa@aaaaaaaa@aa#"
    ],
    [
      "#aa@aaaaaaaa@aa#",
      "aWWWWWWWWWWWWWWa",
      "aWWWWWWWWWWWWWWa",
      "@WWWWWWWWWWWWWW@",
      "aWWWWWWWWWWWWWWa",
      "aaaaaaaaaaaaaaaa",
      "a              a",
      "a              a",
      "aL             a",
      "a      l       a",
      "a     ###::::::a",
      "a      :       a",
      "@      :       @",
      "a      :       a",
      "a      :       a",
      "#aa@aaaaaaaa@aa#"
    ],
    [
      "#aa@aaaaaaaa@aa#",
      "aWWWWWWWWWWWWWWa",
      "aWWWWWWWWWWWWWWa",
      "@WWWWWWWWWWWWWW@",
      "aWWWWWWWWWWWWWWa",
      "aaaaaaaaaaaaaaaa",
      "a              a",
      "a              a",
      "aL             a",
      "a      l       a",
      "a     ###::::::a",
      "a      :       a",
      "@      :       @",
      "a      :       a",
      "a      :       a",
      "#aa@aaaaaaaa@aa#"
    ],
    [
      "################",
      "################",
      "################",
      "################",
      "################",
      "################",
      "################",
      "################",
      "################",
      "#######l########",
      "################",
      "################",
      "##1#1###########",
      "################",
      "################",
      "################"
    ],
    [
      "################",
      "################",
      "################",
      "################",
      "################",
      "################",
      "################",
      "################",
      "################",
      "#######l########",
      "################",
      "################",
      "################",
      "################",
      "################",
      "################"
    ]
  ]
}