{
  "xsize": 16,
  "zsize": 16,
  "slices": [
    [
      "################",
      "################",
      "################",
      "################",
      "################",
      "################",
      "################",
      "################",
      "################",
      "#######l########",
      "################",
      "################",
      "################",
      "################",
      "################",
      "################"
    ],
    [
      "##___######___##",
      "######    ######",
      "_#           F#_",
      "_#   C        #_",
      "_#F           #_",
      "#######  #######",
      "#              #",
      "# .       C  . #",
      "# .          . #",
      "#      l       #",
      "##    ###     ##",
      "_#  C         #_",
      "_#            #_",
      "_#        C   #_",
      "######    ######",
      "##___######___##"
    ],
    [
      "##   ######   ##",
      "##aaa#    #aaa##",
      " a            a ",
      " a            a ",
      " a            a ",
      "##aaaa#  #aaaa##",
      "#              #",
      "# -          - #",
      "# -          - #",
      "#      l       #",
      "##    ###     ##",
      " a            a ",
      " a            a ",
      " a            a ",
      "##aaa#    #aaa##",
      "##   ######   ##"
    ],
    [
      "##   ######   ##",
      "##aaa#    #aaa##",
      " a            a ",
      " a            a ",
      " a    T  T    a ",
      "##aaaa####aaaa##",
      "#              #",
      "#              #",
      "#              #",
      "#      l       #",
      "##T   ###    T##",
      " a            a ",
      " a            a ",
      " a            a ",
      "##aaa#    #aaa##",
      "##   ######   ##"
    ],
    [
      "##   ######   ##",
      "##aaa#    #aaa##",
      " a            a ",
      " a            a ",
      " a            a ",
      "################",
      "#              #",
      "#              #",
      "#              #",
      "#      l       #",
      "##    ###     ##",
      " a            a ",
      " a            a ",
      " a            a ",
      "##aaa#    #aaa##",
      "##   ######   ##"
    ],
    [
      "##===######===##",
      "################",
      "=##############=",
      "=##############=",
      "=##############=",
      "################",
      "################",
      "################",
      "################",
      "#######l########",
      "################",
      "=##############=",
      "=##############=",
      "=##############=",
      "################",
      "##===######===##"
    ]
  ]
}