{
  "xsize": 16,
  "zsize": 16,
  "slices": [
    [
      "#$$#$$#$$#$$#$$#",
      "$##############$",
      "$###4##########$",
      "################",
      "$#####4########$",
      "$##############$",
      "################",
      "$##############$",
      "$##############$",
      "#######l########",
      "$##############$",
      "$##############$",
      "################",
      "$##############$",
      "$##############$",
      "#$$#$$#$$#$$#$$#"
    ],
    [
      "################",
      "#              #",
      "#   ###    C   #",
      "#   ###        #",
      "#   ###        #",
      "#  C           #",
      "##########     #",
      "#        #     #",
      "#   C    #  C  #",
      "#      l #     #",
      "#  #######     #",
      "#             F#",
      "#             L#",
      "#      C       #",
      "#              #",
      "################"
    ],
    [
      "#aa#aa#aa#aa#aa#",
      "a              a",
      "a              a",
      "#    C         #",
      "a              a",
      "a       T      a",
      "####aaa###     #",
      "a       T#     a",
      "a        #     a",
      "#      l #     #",
      "a  #######     a",
      "a              a",
      "#             L#",
      "a              a",
      "a              a",
      "#aa#aa#aa#aa#aa#"
    ],
    [
      "#aa#aa#aa#aa#aa#",
      "a              a",
      "a              a",
      "#              #",
      "a              a",
      "a              a",
      "##########     #",
      "a        #     a",
      "a        #     a",
      "#      l #     #",
      "a  #######     a",
      "a              a",
      "#             L#",
      "a              a",
      "a              a",
      "#aa#aa#aa#aa#aa#"
    ],
    [
      "################",
      "################",
      "################",
      "################",
      "################",
      "################",
      "################",
      "################",
      "################",
      "#######l########",
      "################",
      "################",
      "################",
      "################",
      "################",
      "################"
    ],
    [
      "################",
      "################",
      "################",
      "################",
      "################",
      "################",
      "################",
      "################",
      "################",
      "#######l########",
      "################",
      "################",
      "################",
      "################",
      "################",
      "################"
    ]
  ]
}