{
  "xsize": 16,
  "zsize": 16,
  "slices": [
    [
      "#$$#$$#$$#$$#$$#",
      "$##############$",
      "$##############$",
      "################",
      "$##############$",
      "$##############$",
      "################",
      "$##############$",
      "$##############$",
      "#######l########",
      "$##############$",
      "$##############$",
      "################",
      "$##############$",
      "$##############$",
      "#$$#$$#$$#$$#$$#"
    ],
    [
      "################",
      "#        #     #",
      "#   C    #     #",
      "#       F#     #",
      "#        #   C #",
      "#              #",
      "#        #     #",
      "#    C   #     #",
      "#        #     #",
      "####   l #     #",
      "# C#######     #",
      "#          C   #",
      "#  C           #",
      "#       4   4  #",
      "#  F           #",
      "################"
    ],
    [
      "#aa#aa#aa#aa#aa#",
      "a        #     a",
      "a        #     a",
      "#        #     #",
      "a        #     a",
      "a              a",
      "#       T#     #",
      "a        #     a",
      "a        #     a",
      "####   l #     #",
      "a  #######     a",
      "a              a",
      "#              #",
      "a              a",
      "a              a",
      "#aa#aa#aa#aa#aa#"
    ],
    [
      "#aa#aa#aa#aa#aa#",
      "a        #     a",
      "a        #     a",
      "#        #     #",
      "a        #     a",
      "a        #     a",
      "#        #     #",
      "a        #     a",
      "a        #     a",
      "####   l #     #",
      "a  #######     a",
      "a              a",
      "#              #",
      "a              a",
      "a              a",
      "#aa#aa#aa#aa#aa#"
    ],
    [
      "################",
      "################",
      "################",
      "################",
      "################",
      "################",
      "################",
      "################",
      "################",
      "#######l########",
      "################",
      "################",
      "################",
      "################",
      "################",
      "################"
    ],
    [
      "################",
      "################",
      "################",
      "################",
      "################",
      "################",
      "################",
      "################",
      "################",
      "#######l########",
      "################",
      "################",
      "################",
      "################",
      "################",
      "################"
    ]
  ]
}