{
  "xsize": 16,
  "zsize": 16,
  "slices": [
    [
      "#$$#$$#$$#$$#$$#",
      "$##############$",
      "$###4##########$",
      "################",
      "$#####4########$",
      "$##############$",
      "################",
      "$##############$",
      "$##############$",
      "#######l########",
      "$##############$",
      "$##############$",
      "################",
      "$##############$",
      "$##############$",
      "#$$#$$#$$#$$#$$#"
    ],
    [
      "################",
      "#        #     #",
      "#  C     #   # #",
      "#        #   # #",
      "#     C  #     #",
      "#        #     #",
      "##########     #",
      "#              #",
      "#         C    #",
      "#      l       #",
      "#     ###      #",
      "#  C           #",
      "#              #",
      "#         C    #",
      "#FF            #",
      "################"
    ],
    [
      "#aa#aa#aa#aa#aa#",
      "a        :     a",
      "a        :   * a",
      "#        :   * #",
      "a        :     a",
      "a        :     a",
      "#::::::::#     #",
      "a              a",
      "a              a",
      "#      l       #",
      "a     ###      a",
      "a      T       a",
      "#              #",
      "a              a",
      "a              a",
      "#aa#aa#aa#aa#aa#"
    ],
    [
      "#aa#aa#aa#aa#aa#",
      "a        :     a",
      "a        :     a",
      "#        :     #",
      "a        :     a",
      "a        :     a",
      "#::::::::#     #",
      "a              a",
      "a              a",
      "#      l       #",
      "a     ###      a",
      "a              a",
      "#              #",
      "a              a",
      "a              a",
      "#aa#aa#aa#aa#aa#"
    ],
    [
      "################",
      "################",
      "################",
      "################",
      "################",
      "################",
      "################",
      "################",
      "################",
      "#######l########",
      "################",
      "################",
      "################",
      "################",
      "################",
      "################"
    ],
    [
      "################",
      "################",
      "################",
      "################",
      "################",
      "################",
      "################",
      "################",
      "################",
      "#######l########",
      "################",
      "################",
      "################",
      "################",
      "################",
      "################"
    ]
  ]
}