{
  "xsize": 16,
  "zsize": 16,
  "slices": [
    [
      "##SQSQSQSQSQSQSQ",
      "##QSQSQSQSQSQSQS",
      " #SQSQSQSQSQSQSQ",
      " #QSQSQSQSQSQSQS",
      " #SQSQSQSQSQSQSQ",
      "##QSQSQSQSQSQSQS",
      "aQSQSQSQSQSQSQSQ",
      "aSQSQSQSQSQSQSQS",
      "aQSQSQSQSQSQSQSQ",
      "aSQSQSQSQSQSQSQS",
      "##SQSQSQSQSQSQSQ",
      " #QSQSQSQSQSQSQS",
      " #SQSQSQSQSQSQSQ",
      " #QSQSQSQSQSQSQS",
      "######SQSQ######",
      "##   #aaaa#   ##"
    ],
    [
      "##              ",
      "##    C         ",
      " a              ",
      " a              ",
      " a           C  ",
      "##              ",
      "a               ",
      "a   C   T       ",
      "a               ",
      "a            C  ",
      "##              ",
      " a              ",
      " a     C        ",
      " a              ",
      "##aaa#    #aaa##",
      "##   #aaaa#   ##"
    ],
    [
      "##              ",
      "##              ",
      " a              ",
      " a              ",
      " a              ",
      "##              ",
      "a               ",
      "a               ",
      "a               ",
      "a               ",
      "##              ",
      " a              ",
      " a              ",
      " a              ",
      "##aaa#    #aaa##",
      "##   #aaaa#   ##"
    ],
    [
      "##              ",
      "##              ",
      " a              ",
      " a              ",
      " a              ",
      "##              ",
      "a               ",
      "a               ",
      "a               ",
      "a               ",
      "##              ",
      " a              ",
      " a              ",
      " a              ",
      "##aaa#    #aaa##",
      "##   #aaaa#   ##"
    ],
    [
      "##              ",
      "##              ",
      " a              ",
      " a              ",
      " a              ",
      "##              ",
      "a               ",
      "a               ",
      "a               ",
      "a               ",
      "##              ",
      " a              ",
      " a              ",
      " a              ",
      "##aaa#    #aaa##",
      "##   #aaaa#   ##"
    ],
    [
      "################",
      "################",
      " ###############",
      " ###############",
      " ###############",
      "################",
      "a###############",
      "a###############",
      "a###############",
      "a###############",
      "################",
      " ###############",
      " ###############",
      " ###############",
      "################",
      "##   #aaaa#   ##"
    ]
  ]
}