{
  "xsize": 16,
  "zsize": 16,
  "slices": [
    [
      "##   #aaaa#   ##",
      "######QSQS######",
      "SQSQSQSQSQSQSQ# ",
      "QSQSQSQSQSQSQS# ",
      "SQSQSQSQSQSQSQ# ",
      "QSQSQSQSQSQSQS##",
      "SQSQSQSQSQSQSQSa",
      "QSQSQSQSQSQSQSQa",
      "SQSQSQSQSQSQSQSa",
      "QSQSQSQSQSQSQSQa",
      "SQSQSQSQSQSQSQ##",
      "QSQSQSQSQSQSQS# ",
      "SQSQSQSQSQSQSQ# ",
      "QSQSQSQSQSQSQS# ",
      "SQSQSQSQSQSQSQ##",
      "QSQSQSQSQSQSQS##"
    ],
    [
      "##   #aaaa#   ##",
      "##aaa#    #aaa##",
      "  C           a ",
      "              a ",
      "          C   a ",
      "   +++++++    ##",
      "   +QQQQQ+     a",
      "   +Q4QQQ+     a",
      "   +QQQ4Q+     a",
      " C +QQQQQ+     a",
      "   +++++++    ##",
      "           C  a ",
      "              a ",
      "              a ",
      "   C          ##",
      "              ##"
    ],
    [
      "##   #aaaa#   ##",
      "##aaa#    #aaa##",
      "              a ",
      "              a ",
      "              a ",
      "   +++++++    ##",
      "   +QQQQQ+     a",
      "   +QQQQQ+     a",
      "   +QQQQQ+     a",
      "   +QQQQQ+     a",
      "   +++++++    ##",
      "              a ",
      "              a ",
      "              a ",
      "              ##",
      "              ##"
    ],
    [
      "##   #aaaa#   ##",
      "##aaa#    #aaa##",
      "              a ",
      "              a ",
      "              a ",
      "   +++++++    ##",
      "   +QQQQQ+     a",
      "   +QQQQQ+     a",
      "   +QQQQQ+     a",
      "   +QQQQQ+     a",
      "   +++++++    ##",
      "              a ",
      "              a ",
      "              a ",
      "              ##",
      "              ##"
    ],
    [
      "##   #aaaa#   ##",
      "##aaa#    #aaa##",
      "              a ",
      "              a ",
      "              a ",
      "   +++++++    ##",
      "   +QQQQQ+     a",
      "   +QQQQQ+     a",
      "   +QQQQQ+     a",
      "   +QQQQQ+     a",
      "   +++++++    ##",
      "              a ",
      "              a ",
      "              a ",
      "              ##",
      "              ##"
    ],
    [
      "##   #aaaa#   ##",
      "################",
      "############### ",
      "############### ",
      "############### ",
      "################",
      "###############a",
      "###############a",
      "###############a",
      "###############a",
      "################",
      "############### ",
      "############### ",
      "############### ",
      "################",
      "################"
    ]
  ]
}