{
  "xsize": 16,
  "zsize": 16,
  "slices": [
    [
      "SQSQSQSQSQSQSQ##",
      "Q          SQS##",
      "S     C    QSQ# ",
      "Q          SQS# ",
      "S          QSQ# ",
      "Q          SQS##",
      "S          QSQSa",
      "Q     C    SQSQa",
      "S          QSQSa",
      "Q          SQSQa",
      "S          QSQ##",
      "QSQSQSQSQSQSQS# ",
      "SQSQSQSQSQSQSQ# ",
      "QSQSQSQSQSQSQS# ",
      "######SQSQ######",
      "##   #aaaa#   ##"
    ],
    [
      "::::::::::::  ##",
      ":          :  ##",
      ":          :  a ",
      ":          :  a ",
      ":          :  a ",
      ":          :  ##",
      ":          :   a",
      ":          :   a",
      ":          :   a",
      ":          :   a",
      ":          :  ##",
      "::::::::::::  a ",
      "              a ",
      "              a ",
      "##aaa#    #aaa##",
      "##   #aaaa#   ##"
    ],
    [
      "              ##",
      "              ##",
      "              a ",
      "              a ",
      "              a ",
      "              ##",
      "               a",
      "               a",
      "               a",
      "               a",
      "              ##",
      "              a ",
      "              a ",
      "              a ",
      "##aaa#    #aaa##",
      "##   #aaaa#   ##"
    ],
    [
      "              ##",
      "              ##",
      "              a ",
      "              a ",
      "              a ",
      "              ##",
      "               a",
      "               a",
      "               a",
      "               a",
      "              ##",
      "              a ",
      "              a ",
      "              a ",
      "##aaa#    #aaa##",
      "##   #aaaa#   ##"
    ],
    [
      "              ##",
      "              ##",
      "              a ",
      "              a ",
      "              a ",
      "              ##",
      "               a",
      "               a",
      "               a",
      "               a",
      "              ##",
      "              a ",
      "              a ",
      "              a ",
      "##aaa#    #aaa##",
      "##   #aaaa#   ##"
    ],
    [
      "################",
      "#          #####",
      "#          #### ",
      "#          #### ",
      "#          #### ",
      "#          #####",
      "#          ####a",
      "#          ####a",
      "#          ####a",
      "#          ####a",
      "#          #####",
      "############### ",
      "############### ",
      "############### ",
      "################",
      "##   #aaaa#   ##"
    ]
  ]
}