{
  "xsize": 16,
  "zsize": 16,
  "slices": [
    [
      "##   #aaaa#   ##",
      "######QSQS######",
      " #SQSQSQSQSQSQSQ",
      " #QSQSQSQSQSQSQS",
      " #SQSQSQSQSQSQSQ",
      "##QSQSQSQSQSQSQS",
      "aQSQSQSQSQSQSQSQ",
      "aSQSQSQSQSQSQSQS",
      "aQSQSQSQSQSQSQSQ",
      "aSQSQSQSQSQSQSQS",
      "##SQSQSQSQSQS  Q",
      " #QSQSQSQSQSQ  S",
      " #SQSQSQSQSQS  Q",
      " #QSQSQSQSQSQ  S",
      "##SQSQSQSQSQS))Q",
      "##QSQSQSQSQSQSQS"
    ],
    [
      "##   #aaaa#   ##",
      "##aaa#    #aaa##",
      " a              ",
      " a     C        ",
      " a              ",
      "##              ",
      "a            C  ",
      "a               ",
      "a  C            ",
      "a            )) ",
      "#########   Q  Q",
      " a C  #4#   Q  Q",
      " a    #4#   Q  Q",
      " a    #4#   Q  Q",
      "### #####C  Q  Q",
      "##              "
    ],
    [
      "##   #aaaa#   ##",
      "##aaa#    #aaa##",
      " a              ",
      " a              ",
      " a              ",
      "##              ",
      "a               ",
      "a               ",
      "a               ",
      "a    T          ",
      "#########   a))a",
      " a    ###   a  a",
      " a    ###   a  a",
      " a    ###   a  a",
      "### #####   a  a",
      "##              "
    ],
    [
      "##   #aaaa#   ##",
      "##aaa#    #aaa##",
      " a              ",
      " a              ",
      " a              ",
      "##              ",
      "a               ",
      "a               ",
      "a               ",
      "a               ",
      "#########   a  a",
      " a    #4#   a))a",
      " a    #1#   a  a",
      " a    #1#   a  a",
      "### #####   a  a",
      "##              "
    ],
    [
      "##   #aaaa#   ##",
      "##aaa#    #aaa##",
      " a              ",
      " a              ",
      " a              ",
      "##              ",
      "a               ",
      "a               ",
      "a               ",
      "a               ",
      "#########   a  a",
      " a    ###   a  a",
      " a    ###   a))a",
      " a    ###   a  a",
      "### #####   a  a",
      "##              "
    ],
    [
      "##   #aaaa#   ##",
      "################",
      " ###############",
      " ###############",
      " ###############",
      "################",
      "a###############",
      "a###############",
      "a###############",
      "a###############",
      "#############  #",
      " ############  #",
      " ############  #",
      " ############))#",
      "#############  #",
      "################"
    ]
  ]
}