{
  "xsize": 16,
  "zsize": 16,
  "slices": [
    [
      "##SQSQSQSQSQSQSQ",
      "##QSQSQSQSQSQSQS",
      " #SQSQSQSQSQSQSQ",
      " #QSQSQSQSQSQSQS",
      " #SQSQSQSQSQSQSQ",
      "##QSQSQSQSQSQSQS",
      "aQSQSQSQSQSQSQSQ",
      "aSQSQSQSQSQSQSQS",
      "aQSQSQSQSQSQSQSQ",
      "aSQSQSQSQSQSQSQS",
      "##SQSQSQSQSQSQSQ",
      " #QSQSQSQSQSQSQS",
      " #SQSQSQSQSQSQSQ",
      " #QSQSQSQSQSQSQS",
      "######SQSQ######",
      "##   #aaaa#   ##"
    ],
    [
      "##              ",
      "##    #+:+:+:+# ",
      " a  C ######### ",
      " a    #+:+:+:+# ",
      " a          C   ",
      "##    #+:+:+:+# ",
      "a     ######### ",
      "a  C  #+:+:+:+# ",
      "a            C  ",
      "a     #+:+:+:+# ",
      "##    ######### ",
      " a    #+:+:+:+# ",
      " a              ",
      " a      C       ",
      "##aaa#    #aaa##",
      "##   #aaaa#   ##"
    ],
    [
      "##              ",
      "##    #+:+:+:+# ",
      " a   T######### ",
      " a    #+:+:+:+# ",
      " a              ",
      "##    #+:+:+:+# ",
      "a    T######### ",
      "a     #+:+:+:+# ",
      "a               ",
      "a     #+:+:+:+# ",
      "##   T######### ",
      " a    #+:+:+:+# ",
      " a              ",
      " a              ",
      "##aaa#    #aaa##",
      "##   #aaaa#   ##"
    ],
    [
      "##              ",
      "##    #+:+:+:+# ",
      " a    ######### ",
      " a    #+:+:+:+# ",
      " a              ",
      "##    #+:+:+:+# ",
      "a     ######### ",
      "a     #+:+:+:+# ",
      "a               ",
      "a     #+:+:+:+# ",
      "##    ######### ",
      " a    #+:+:+:+# ",
      " a              ",
      " a              ",
      "##aaa#    #aaa##",
      "##   #aaaa#   ##"
    ],
    [
      "##              ",
      "##    #+:+:+:+# ",
      " a    ######### ",
      " a    #+:+:+:+# ",
      " a              ",
      "##    #+:+:+:+# ",
      "a     ######### ",
      "a     #+:+:+:+# ",
      "a               ",
      "a     #+:+:+:+# ",
      "##    ######### ",
      " a    #+:+:+:+# ",
      " a              ",
      " a              ",
      "##aaa#    #aaa##",
      "##   #aaaa#   ##"
    ],
    [
      "################",
      "################",
      " ###############",
      " ###############",
      " ###############",
      "################",
      "a###############",
      "a###############",
      "a###############",
      "a###############",
      "################",
      " ###############",
      " ###############",
      " ###############",
      "################",
      "##   #aaaa#   ##"
    ]
  ]
}