{
  "xsize": 16,
  "zsize": 16,
  "slices": [
    [
      "##   #aaaa#   ##",
      "######QSQS######",
      " #SQSQSQSQSQSQSQ",
      " #QSQSQSQSQSQSQS",
      " #SQSQSQSQSQSQSQ",
      "##QSQSQSQSQSQSQS",
      "aQSQSQSQSQSQSQSQ",
      "aSQSQSQSQSQSQSQS",
      "aQSQSQSQSQSQSQSQ",
      "aSQSQSQSQSQSQSQS",
      "##SQSQSQSQSQS  Q",
      " #QSQSQSQSQSQ  S",
      " #SQSQSQSQSQS  Q",
      " #QSQSQSQSQSQ  S",
      "##SQSQSQSQSQS))Q",
      "##QSQSQSQSQSQSQS"
    ],
    [
      "##   #aaaa#   ##",
      "##aaa#    #aaa##",
      " a              ",
      " a   C          ",
      " a           C  ",
      "##              ",
      "a               ",
      "a   C           ",
      "a               ",
      "a            )) ",
      "##       C  Q  Q",
      " a          Q  Q",
      " a          Q  Q",
      " a          Q  Q",
      "##   C      Q  Q",
      "##              "
    ],
    [
      "##   #aaaa#   ##",
      "##aaa#    #aaa##",
      " a              ",
      " a              ",
      " a              ",
      "##              ",
      "a               ",
      "a               ",
      "a               ",
      "a               ",
      "##          a))a",
      " a          a  a",
      " a          a  a",
      " a          a  a",
      "##          a  a",
      "##              "
    ],
    [
      "##   #aaaa#   ##",
      "##aaa#    #aaa##",
      " a              ",
      " a              ",
      " a              ",
      "##              ",
      "a               ",
      "a               ",
      "a               ",
      "a               ",
      "##          a  a",
      " a          a))a",
      " a          a  a",
      " a          a  a",
      "##          a  a",
      "##              "
    ],
    [
      "##   #aaaa#   ##",
      "##aaa#    #aaa##",
      " a              ",
      " a              ",
      " a              ",
      "##              ",
      "a               ",
      "a               ",
      "a               ",
      "a               ",
      "##          a  a",
      " a          a  a",
      " a          a))a",
      " a          a  a",
      "##          a  a",
      "##              "
    ],
    [
      "##   #aaaa#   ##",
      "################",
      " ###############",
      " ###############",
      " ###############",
      "################",
      "a###############",
      "a###############",
      "a###############",
      "a###############",
      "#############  #",
      " ############  #",
      " ############  #",
      " ############))#",
      "#############  #",
      "################"
    ]
  ]
}