{
  "xsize": 16,
  "zsize": 16,
  "slices": [
    [
      "##   #aaaa#   ##",
      "######QSQS######",
      "SQSQSQSQSQSQSQ# ",
      "QSQSQSQSQSQSQS# ",
      "SQSQSQSQSQSQSQ# ",
      "QSQSQSQSQSQSQS##",
      "SQSQSQSQSQSQSQSa",
      "QSQSQSQSQSQSQSQa",
      "SQSQSQSQSQSQSQSa",
      "QSQSQSQSQSQSQSQa",
      "SQSQSQSQSQSQSQ##",
      "QSQSQSQSQSQSQS# ",
      "SQSQSQSQSQSQSQ# ",
      "QSQSQSQSQSQSQS# ",
      "SQSQSQSQSQSQSQ##",
      "QSQSQSQSQSQSQS##"
    ],
    [
      "##   #aaaa#   ##",
      "##aaa#    #aaa##",
      "   C          a ",
      "              a ",
      "           C  a ",
      "  ###   ###   ##",
      "  +#+   +#+    a",
      "  :#:   :#:    a",
      " C+#+   +#+    a",
      "  :#:   :#:    a",
      "  +#+   +#+   ##",
      "  :#:   :#:   a ",
      "  +#+ C +#+   a ",
      "  :#:   :#: C a ",
      "  +#+   +#+   ##",
      "  ###   ###   ##"
    ],
    [
      "##   #aaaa#   ##",
      "##aaa#    #aaa##",
      "              a ",
      "              a ",
      "   T     T    a ",
      "  ###   ###   ##",
      "  +#+   +#+    a",
      "  :#:   :#:    a",
      "  +#+   +#+    a",
      "  :#:   :#:    a",
      "  +#+   +#+   ##",
      "  :#:   :#:   a ",
      "  +#+   +#+   a ",
      "  :#:   :#:   a ",
      "  +#+   +#+   ##",
      "  ###   ###   ##"
    ],
    [
      "##   #aaaa#   ##",
      "##aaa#    #aaa##",
      "              a ",
      "              a ",
      "              a ",
      "  ###   ###   ##",
      "  +#+   +#+    a",
      "  :#:   :#:    a",
      "  +#+   +#+    a",
      "  :#:   :#:    a",
      "  +#+   +#+   ##",
      "  :#:   :#:   a ",
      "  +#+   +#+   a ",
      "  :#:   :#:   a ",
      "  +#+   +#+   ##",
      "  ###   ###   ##"
    ],
    [
      "##   #aaaa#   ##",
      "##aaa#    #aaa##",
      "              a ",
      "              a ",
      "              a ",
      "  ###   ###   ##",
      "  +#+   +#+    a",
      "  :#:   :#:    a",
      "  +#+   +#+    a",
      "  :#:   :#:    a",
      "  +#+   +#+   ##",
      "  :#:   :#:   a ",
      "  +#+   +#+   a ",
      "  :#:   :#:   a ",
      "  +#+   +#+   ##",
      "  ###   ###   ##"
    ],
    [
      "##   #aaaa#   ##",
      "################",
      "############### ",
      "############### ",
      "############### ",
      "################",
      "###############a",
      "###############a",
      "###############a",
      "###############a",
      "################",
      "############### ",
      "############### ",
      "############### ",
      "################",
      "################"
    ]
  ]
}