{
  "xsize": 16,
  "zsize": 16,
  "slices": [
    [
      "################",
      "#SSSSSSSSSSSSSSS",
      "#SSSSSSSSSSSSSSS",
      "#SS#############",
      "#SS#QQQQQQQQQQQQ",
      "#SS#QQQQQQQQQQQQ",
      "#SS#QQQQQQQQQQQQ",
      "#SS#QQQQQQQQQQQQ",
      "#SS#QQQQQQQQQQQQ",
      "#SS#QQQQQQQQQQQQ",
      "#SS#QQQQQQQQQ  Q",
      "#SS#QQQQQQQQQ  Q",
      "#SS#QQQQQQQQQ  Q",
      "#SS#QQQQQQQQQ  Q",
      "#SS#QQQQQQQQQ))Q",
      "#SS#QQQQQQQQQQQQ"
    ],
    [
      "aa#aaaa#aaaa#aaa",
      "a      C        ",
      "#               ",
      "a             C ",
      "a      LLLL     ",
      "a               ",
      "a   C  LLLL     ",
      "#               ",
      "a               ",
      "a            )) ",
      "a       C   w  w",
      "a           w  w",
      "#           w  w",
      "a           w  w",
      "a   C       w  w",
      "a               "
    ],
    [
      "aa#aaaa#aaaa#aaa",
      "a               ",
      "#               ",
      "a               ",
      "a      LLLLT    ",
      "a               ",
      "a      LLLLT    ",
      "#               ",
      "a               ",
      "a               ",
      "a           :)):",
      "a           :  :",
      "#           :  :",
      "a           :  :",
      "a           :  :",
      "a               "
    ],
    [
      "aa#aaaa#aaaa#aaa",
      "a               ",
      "#               ",
      "a               ",
      "a      LLLL     ",
      "a               ",
      "a      LLLL     ",
      "#               ",
      "a               ",
      "a               ",
      "a           :  :",
      "a           :)):",
      "#           :  :",
      "a           :  :",
      "a           :  :",
      "a               "
    ],
    [
      "################",
      "#        %      ",
      "#               ",
      "#               ",
      "#               ",
      "#               ",
      "#               ",
      "#               ",
      "#               ",
      "#               ",
      "#          %:  :",
      "#           :  :",
      "#           :)):",
      "#          %:  :",
      "#           :  :",
      "#               "
    ],
    [
      "################",
      "################",
      "################",
      "################",
      "################",
      "################",
      "################",
      "################",
      "################",
      "################",
      "#############  #",
      "#############  #",
      "#############  #",
      "#############))#",
      "#############  #",
      "################"
    ]
  ]
}