{
  "xsize": 16,
  "zsize": 16,
  "slices": [
    [
      "################",
      "SSSSSSSSSSSSSSS#",
      "SSSSSSSSSSSSSSS#",
      "#############SS#",
      "QQQQQQQQQQQQ#SS#",
      "QQQQQQQQQQQQ#SS#",
      "QQQQQQQQQQQQ#SS#",
      "QQQQQQQQQQQQ#SS#",
      "QQQQQQQQQQQQ#SS#",
      "QQQQQQQQQQQQ#SS#",
      "QQQQQQQQQQQQ#SS#",
      "QQQQQQQQQQQQ#SS#",
      "QQQQQQQQQQQQ#SS#",
      "QQQQQQQQQQQQ#SS#",
      "QQQQQQQQQQQQ#SS#",
      "QQQQQQQQQQQQ#SS#"
    ],
    [
      "aaa#aaaa#aaaa#aa",
      "   C           a",
      "               #",
      "               a",
      "     LLLLL  C  a",
      "               a",
      "               a",
      "     .  .  .   #",
      "  C            a",
      "               a",
      "     .  .  .   a",
      "            C  a",
      "               #",
      "     LLLLL     a",
      "      C        a",
      "               a"
    ],
    [
      "aaa#aaaa#aaaa#aa",
      "               a",
      "               #",
      "               a",
      "    TLLLLL     a",
      "               a",
      "               a",
      "     -  -  -   #",
      "               a",
      "               a",
      "     -  -  -   a",
      "               a",
      "               #",
      "    TLLLLL     a",
      "               a",
      "               a"
    ],
    [
      "aaa#aaaa#aaaa#aa",
      "               a",
      "               #",
      "               a",
      "     LLLLL     a",
      "               a",
      "               a",
      "               #",
      "               a",
      "               a",
      "               a",
      "               a",
      "               #",
      "     LLLLL     a",
      "               a",
      "               a"
    ],
    [
      "################",
      "               #",
      "               #",
      "               #",
      "               #",
      "               #",
      "               #",
      "               #",
      "               #",
      "               #",
      "               #",
      "               #",
      "               #",
      "               #",
      "               #",
      "               #"
    ],
    [
      "################",
      "################",
      "################",
      "################",
      "################",
      "################",
      "################",
      "################",
      "################",
      "################",
      "################",
      "################",
      "################",
      "################",
      "################",
      "################"
    ]
  ]
}