{
  "xsize": 16,
  "zsize": 16,
  "slices": [
    [
      "################",
      "SSSSSSSSSSSSSSS#",
      "SSSSSSSSSSSSSSS#",
      "#############SS#",
      "QQQQQQQQQQQQ#SS#",
      "QQQQQQQQQQQQ#SS#",
      "QQQQQQQQQQQQ#SS#",
      "QQQQQQQQQQQQ#SS#",
      "QQQQQQQQQQQQ#SS#",
      "QQQQQQQQQQQQ#SS#",
      "QQQQQQQQQQQQ#SS#",
      "QQQQQQQQQQQQ#SS#",
      "QQQQQQQQQQQQ#SS#",
      "QQQQQQQQQQQQ#SS#",
      "QQQQQQQQQQQQ#SS#",
      "QQQQQQQQQQQQ#SS#"
    ],
    [
      "aaa#aaaa#aaaa#aa",
      "               a",
      "  C            #",
      "               a",
      "     LLLL      a",
      "           C   a",
      "     LLLL      a",
      "               #",
      "     LLLL      a",
      "   C           a",
      "               a",
      "           C   a",
      "               #",
      "               a",
      "     C         a",
      "               a"
    ],
    [
      "aaa#aaaa#aaaa#aa",
      "               a",
      "               #",
      "               a",
      "    TLLLL      a",
      "               a",
      "     LLLL      a",
      "               #",
      "    TLLLL      a",
      "               a",
      "               a",
      "               a",
      "               #",
      "               a",
      "               a",
      "               a"
    ],
    [
      "aaa#aaaa#aaaa#aa",
      "               a",
      "               #",
      "               a",
      "     LLLL      a",
      "               a",
      "     LLLL      a",
      "               #",
      "     LLLL      a",
      "               a",
      "               a",
      "               a",
      "               #",
      "               a",
      "               a",
      "               a"
    ],
    [
      "################",
      "               #",
      "               #",
      "               #",
      "               #",
      "               #",
      "               #",
      "               #",
      "       %%      #",
      "               #",
      "               #",
      "               #",
      "               #",
      "               #",
      "               #",
      "               #"
    ],
    [
      "################",
      "################",
      "################",
      "################",
      "################",
      "################",
      "################",
      "################",
      "################",
      "################",
      "################",
      "################",
      "################",
      "################",
      "################",
      "################"
    ]
  ]
}