{
  "xsize": 16,
  "zsize": 16,
  "slices": [
    [
      "#SS#QQQQQQQQQQQQ",
      "#SS#QQQQQQQQQQQQ",
      "#SS#QQQQQQQQQQQQ",
      "#SS#QQQQQQQQQQQQ",
      "#SS#QQQQQQQQQQQQ",
      "#SS#QQQQQQQQQQQQ",
      "#SS#QQQQQQQQQQQQ",
      "#SS#QQQQQQQQQQQQ",
      "#SS#QQQQQQQQQQQQ",
      "#SS#QQQQQQQQQQQQ",
      "#SS#QQQQQQQQQQQQ",
      "#SS#QQQQQQQQQQQQ",
      "#SS#############",
      "#SSSSSSSSSSSSSSS",
      "#SSSSSSSSSSSSSSS",
      "################"
    ],
    [
      "a               ",
      "a    C          ",
      "a               ",
      "#       %    C  ",
      "a      LLLL     ",
      "a               ",
      "a      LLLL     ",
      "a  C     %%     ",
      "#      LLLL     ",
      "a               ",
      "a      LLLL     ",
      "a      %%    C  ",
      "a               ",
      "#               ",
      "a      C        ",
      "aa#aaaa#aaaa#aaa"
    ],
    [
      "a               ",
      "a               ",
      "a               ",
      "#               ",
      "a      LLLLT    ",
      "a               ",
      "a      LLLL     ",
      "a               ",
      "#      LLLL     ",
      "a               ",
      "a      LLLLT    ",
      "a               ",
      "a               ",
      "#               ",
      "a               ",
      "aa#aaaa#aaaa#aaa"
    ],
    [
      "a               ",
      "a               ",
      "a               ",
      "#               ",
      "a      LLLL     ",
      "a               ",
      "a      LLLL     ",
      "a               ",
      "#      LLLL     ",
      "a               ",
      "a      LLLL     ",
      "a               ",
      "a               ",
      "#               ",
      "a               ",
      "aa#aaaa#aaaa#aaa"
    ],
    [
      "#               ",
      "#               ",
      "#               ",
      "#               ",
      "#               ",
      "#               ",
      "#               ",
      "#               ",
      "#               ",
      "#               ",
      "#               ",
      "#               ",
      "#               ",
      "#               ",
      "#               ",
      "################"
    ],
    [
      "################",
      "################",
      "################",
      "################",
      "################",
      "################",
      "################",
      "################",
      "################",
      "################",
      "################",
      "################",
      "################",
      "################",
      "################",
      "################"
    ]
  ]
}