{
  "xsize": 16,
  "zsize": 16,
  "slices": [
    [
      "#SS#QQQQQQQQQQQQ",
      "#SS#QQQQQQQQQQQQ",
      "#SS#QQQQQQQQQQQQ",
      "#SS#QQQQQQQQQQQQ",
      "#SS#QQQQQQQQQQQQ",
      "#SS#QQQQQQQQQQQQ",
      "#SS#QQQQQQQQQQQQ",
      "#SS#QQQQQQQQQQQQ",
      "#SS#QQQQQQQQQQQQ",
      "#SS#QQQQQQQQQQQQ",
      "#SS#QQQQQQQQQQQQ",
      "#SS#QQQQQQQQQQQQ",
      "#SS#############",
      "#SSSSSSSSSSSSSSS",
      "#SSSSSSSSSSSSSSS",
      "################"
    ],
    [
      "a               ",
      "a   C           ",
      "a               ",
      "#             C ",
      "a      LLLL     ",
      "a     QQQQQQ    ",
      "a  C  QLLLLQ    ",
      "a     Q    Q    ",
      "#         C     ",
      "a     Q    Q    ",
      "a     QLLLLQ    ",
      "a     QQQQQQ    ",
      "a      LLLL     ",
      "#               ",
      "a       C       ",
      "aa#aaaa#aaaa#aaa"
    ],
    [
      "a               ",
      "a               ",
      "a               ",
      "#               ",
      "a               ",
      "a      **       ",
      "a               ",
      "a               ",
      "#               ",
      "a               ",
      "a               ",
      "a        * *    ",
      "a               ",
      "#               ",
      "a               ",
      "aa#aaaa#aaaa#aaa"
    ],
    [
      "a               ",
      "a               ",
      "a               ",
      "#               ",
      "a               ",
      "a               ",
      "a               ",
      "a               ",
      "#               ",
      "a               ",
      "a               ",
      "a               ",
      "a               ",
      "#               ",
      "a               ",
      "aa#aaaa#aaaa#aaa"
    ],
    [
      "#               ",
      "#               ",
      "#               ",
      "#               ",
      "#               ",
      "#               ",
      "#               ",
      "#               ",
      "#               ",
      "#               ",
      "#               ",
      "#               ",
      "#               ",
      "#               ",
      "#               ",
      "################"
    ],
    [
      "################",
      "################",
      "################",
      "################",
      "################",
      "################",
      "################",
      "################",
      "################",
      "################",
      "################",
      "################",
      "################",
      "################",
      "################",
      "################"
    ]
  ]
}