{
  "xsize": 16,
  "zsize": 16,
  "slices": [
    [
      "#SS#QQQQQQQQQQQQ",
      "#SS#QQQQQQQQQQQQ",
      "#SS#QQQQQQQQQQQQ",
      "#SS#QQQQQQQQQQQQ",
      "#SS#QQQQQQQQQQQQ",
      "#SS#QQQQQQQQQQQQ",
      "#SS#QQQQQQQQQQQQ",
      "#SS#QQQQQQQQQQQQ",
      "#SS#QQQQQQQQQQQQ",
      "#SS#QQQQQQQQQQQQ",
      "#SS#QQQQQQQQQQQQ",
      "#SS#QQQQQQQQQQQQ",
      "#SS#############",
      "#SSSSSSSSSSSSSSS",
      "#SSSSSSSSSSSSSSS",
      "################"
    ],
    [
      "a               ",
      "a        C      ",
      "a               ",
      "#               ",
      "a               ",
      "a               ",
      "a      C        ",
      "a               ",
      "###:::::::###   ",
      "a               ",
      "a  CLLL     #   ",
      "a           :   ",
      "a   LLL     : C ",
      "#       C   #   ",
      "a F         #   ",
      "aa#aaaa#aaaa#aaa"
    ],
    [
      "a               ",
      "a               ",
      "a               ",
      "#               ",
      "a               ",
      "a               ",
      "a               ",
      "a               ",
      "###:::::::###   ",
      "a               ",
      "a   LLL     #   ",
      "a           :   ",
      "a   LLLT    :   ",
      "#           #   ",
      "a           #   ",
      "aa#aaaa#aaaa#aaa"
    ],
    [
      "a               ",
      "a               ",
      "a               ",
      "#               ",
      "a               ",
      "a               ",
      "a               ",
      "a               ",
      "###:::::::###   ",
      "a           #   ",
      "a   LLL     #   ",
      "a           :   ",
      "a   LLL     :   ",
      "#           #   ",
      "a           #   ",
      "aa#aaaa#aaaa#aaa"
    ],
    [
      "#               ",
      "#               ",
      "#               ",
      "#               ",
      "#               ",
      "#               ",
      "#               ",
      "#               ",
      "###:::::::###   ",
      "#           #   ",
      "#           #   ",
      "#           :   ",
      "#           :   ",
      "#           #   ",
      "#           #   ",
      "################"
    ],
    [
      "################",
      "################",
      "################",
      "################",
      "################",
      "################",
      "################",
      "################",
      "################",
      "################",
      "################",
      "################",
      "################",
      "################",
      "################",
      "################"
    ]
  ]
}