{
  "xsize": 16,
  "zsize": 16,
  "slices": [
    [
      "################",
      "SSSSSSSSSSSSSSS#",
      "SSSSSSSSSSSSSSS#",
      "#############SS#",
      "QQQQQQQQQQQQ#SS#",
      "QQQQQQQQQQQQ#SS#",
      "QQQQQQQQQQQQ#SS#",
      "QQQQQQQQQQQQ#SS#",
      "QQQQQQQQQQQQ#SS#",
      "QQQQQQQQQQQQ#SS#",
      "QQQQQQQQQQQQ#SS#",
      "QQQQQQQQQQQQ#SS#",
      "QQQQQQQQQQQQ#SS#",
      "QQQQQQQQQQQQ#SS#",
      "QQQQQQQQQQQQ#SS#",
      "QQQQQQQQQQQQ#SS#"
    ],
    [
      "aaa#aaaa#aaaa#aa",
      "  C            a",
      "               #",
      "    FLLLLF     a",
      "  ########## C a",
      "  #4######4#   a",
      "  ##########   a",
      "  ###  C ###F  #",
      "  ###    ###L  a",
      "  ###    ###L  a",
      "  C      ###L  a",
      "  ###    ###F  a",
      "  ##########   #",
      "  #4######4#   a",
      "  ########## C a",
      "    FLLLLF     a"
    ],
    [
      "aaa#aaaa#aaaa#aa",
      "               a",
      "               #",
      "   T LLLL      a",
      "  ##########   a",
      "  ##########   a",
      "  ##########   a",
      "  ###    ###   #",
      "  ###    ###L  a",
      "  ###    ###L  a",
      "         ###L  a",
      "  ###    ###   a",
      "  ##########   #",
      "  ##########   a",
      "  ##########   a",
      "     LLLL      a"
    ],
    [
      "aaa#aaaa#aaaa#aa",
      "               a",
      "               #",
      "     LLLL      a",
      "  ##########   a",
      "  ##########   a",
      "  ##########   a",
      "  ###    ###   #",
      "  ###    ###L  a",
      "  ###    ###L  a",
      "  ###    ###L  a",
      "  ###    ###   a",
      "  ##########   #",
      "  ##########   a",
      "  ##########   a",
      "     LLLL      a"
    ],
    [
      "################",
      "               #",
      "               #",
      "               #",
      "  ##########   #",
      "  ##########   #",
      "  ##########   #",
      "  ###%  %###   #",
      "  ###    ###   #",
      "  ###    ###   #",
      "  ###    ###   #",
      "  ###%  %###   #",
      "  ##########   #",
      "  ##########   #",
      "  ##########   #",
      "               #"
    ],
    [
      "################",
      "################",
      "################",
      "################",
      "################",
      "################",
      "################",
      "################",
      "################",
      "################",
      "################",
      "################",
      "################",
      "################",
      "################",
      "################"
    ]
  ]
}