{
  "xsize": 16,
  "zsize": 16,
  "slices": [
    [
      "QQQQQQQQQQQQ#SS#",
      "QQQQQQQQQQQQ#SS#",
      "QQQQQQQQQQQQ#SS#",
      "QQQQQQQQQQQQ#SS#",
      "QQQQQQQQQQQQ#SS#",
      "QQQQQQQQQQQQ#SS#",
      "QQQQQQQQQQQQ#SS#",
      "QQQQQQQQQQQQ#SS#",
      "QQQQQQQQQQQQ#SS#",
      "QQQQQQQQQQQQ#SS#",
      "QQQQQQQQQQQQ#SS#",
      "QQQQQQQQQQQQ#SS#",
      "#############SS#",
      "SSSSSSSSSSSSSSS#",
      "SSSSSSSSSSSSSSS#",
      "################"
    ],
    [
      "               a",
      "   C           a",
      "               a",
      "            C  #",
      "      LLLL     a",
      "               a",
      "  C   LLLL     a",
      "               a",
      "      LLLL     #",
      "         C     a",
      "      LLLL     a",
      "               a",
      "               a",
      "        C      #",
      "               a",
      "aaa#aaaa#aaaa#aa"
    ],
    [
      "               a",
      "               a",
      "               a",
      "               #",
      "     TLLLL     a",
      "               a",
      "      LLLL     a",
      "               a",
      "      LLLL     #",
      "               a",
      "     TLLLL     a",
      "               a",
      "               a",
      "               #",
      "               a",
      "aaa#aaaa#aaaa#aa"
    ],
    [
      "               a",
      "               a",
      "               a",
      "               #",
      "      LLLL     a",
      "               a",
      "      LLLL     a",
      "               a",
      "      LLLL     #",
      "               a",
      "      LLLL     a",
      "               a",
      "               a",
      "               #",
      "               a",
      "aaa#aaaa#aaaa#aa"
    ],
    [
      "               #",
      "               #",
      "               #",
      "               #",
      "               #",
      "      %        #",
      "               #",
      "       %       #",
      "               #",
      "               #",
      "               #",
      "               #",
      "               #",
      "               #",
      "               #",
      "################"
    ],
    [
      "################",
      "################",
      "################",
      "################",
      "################",
      "################",
      "################",
      "################",
      "################",
      "################",
      "################",
      "################",
      "################",
      "################",
      "################",
      "################"
    ]
  ]
}