{
  "xsize": 16,
  "zsize": 16,
  "slices": [
    [
      "################",
      "SSSSSSSSSSSSSSS#",
      "SSSSSSSSSSSSSSS#",
      "#############SS#",
      "QQQQQQQQQQQQ#SS#",
      "QQQQQQQQQQQQ#SS#",
      "QQQQQQQQQQQQ#SS#",
      "QQQQQQQQQQQQ#SS#",
      "QQQQQQQQQQQQ#SS#",
      "QQQQQQQQQQQQ#SS#",
      "QQQQQQQQQQQQ#SS#",
      "QQQQQQQQQQQQ#SS#",
      "QQQQQQQQQQQQ#SS#",
      "QQQQQQQQQQQQ#SS#",
      "QQQQQQQQQQQQ#SS#",
      "QQQQQQQQQQQQ#SS#"
    ],
    [
      "aaa#aaaa#aaaa#aa",
      "  C            a",
      "               #",
      "           C   a",
      "     LLLLLL    a",
      "               a",
      "     LLLLLL%   a",
      "               #",
      "  C  LLLLLL    a",
      "               a",
      "    %LLLLLL  C a",
      "               a",
      "     LLLLLL    #",
      "               a",
      "      C        a",
      "               a"
    ],
    [
      "aaa#aaaa#aaaa#aa",
      "               a",
      "               #",
      "               a",
      "    TLLLLLL    a",
      "               a",
      "     LLLLLL    a",
      "               #",
      "     LLLLLL    a",
      "               a",
      "     LLLLLL    a",
      "               a",
      "    TLLLLLL    #",
      "               a",
      "               a",
      "               a"
    ],
    [
      "aaa#aaaa#aaaa#aa",
      "               a",
      "               #",
      "               a",
      "     LLLLLL    a",
      "               a",
      "     LLLLLL    a",
      "               #",
      "     LLLLLL    a",
      "               a",
      "     LLLLLL    a",
      "               a",
      "               #",
      "               a",
      "               a",
      "               a"
    ],
    [
      "################",
      "               #",
      "               #",
      "               #",
      "     %         #",
      "               #",
      "        %      #",
      "               #",
      "               #",
      "               #",
      "               #",
      "               #",
      "               #",
      "               #",
      "               #",
      "               #"
    ],
    [
      "################",
      "################",
      "################",
      "################",
      "################",
      "################",
      "################",
      "################",
      "################",
      "################",
      "################",
      "################",
      "################",
      "################",
      "################",
      "################"
    ]
  ]
}