{
  "xsize": 16,
  "zsize": 16,
  "slices": [
    [
      "QQQQQQQQQQQQ#SS#",
      "QQQQQQQQQQQQ#SS#",
      "QQQQQQQQQQQQ#SS#",
      "QQQQQQQQQQQQ#SS#",
      "QQQQQQQQQQQQ#SS#",
      "QQQQQQQQQQQQ#SS#",
      "QQQQQQQQQQQQ#SS#",
      "QQQQQQQQQQQQ#SS#",
      "QQQQQQQQQQQQ#SS#",
      "QQQQQQQQQQQQ#SS#",
      "QQQQQQQQQQQQ#SS#",
      "QQQQQQQQQQQQ#SS#",
      "#############SS#",
      "SSSSSSSSSSSSSSS#",
      "SSSSSSSSSSSSSSS#",
      "################"
    ],
    [
      "               a",
      "   C           a",
      "               a",
      "           C   #",
      "      LLLL     a",
      "      QQQQ     a",
      "      LLLL     a",
      "  C            a",
      "      LLLL     #",
      "      QQQQ     a",
      "      LLLL  C  a",
      "               a",
      "               a",
      "      C        #",
      "               a",
      "aaa#aaaa#aaaa#aa"
    ],
    [
      "               a",
      "               a",
      "               a",
      "               #",
      "     TLLLL     a",
      "      QQQQ     a",
      "      LLLL     a",
      "               a",
      "      LLLL     #",
      "      QQQQ     a",
      "     TLLLL     a",
      "               a",
      "               a",
      "               #",
      "               a",
      "aaa#aaaa#aaaa#aa"
    ],
    [
      "               a",
      "               a",
      "               a",
      "               #",
      "               a",
      "      QQQQ     a",
      "               a",
      "               a",
      "               #",
      "      QQQQ     a",
      "               a",
      "               a",
      "               a",
      "               #",
      "               a",
      "aaa#aaaa#aaaa#aa"
    ],
    [
      "               #",
      "               #",
      "               #",
      "               #",
      "         %     #",
      "      QQQQ     #",
      "       %%      #",
      "               #",
      "               #",
      "      QQQQ%    #",
      "      %        #",
      "               #",
      "               #",
      "               #",
      "   %           #",
      "################"
    ],
    [
      "################",
      "################",
      "################",
      "################",
      "################",
      "################",
      "################",
      "################",
      "################",
      "################",
      "################",
      "################",
      "################",
      "################",
      "################",
      "################"
    ]
  ]
}