{
  "refpalette": "oilrig",
  "xsize": 16,
  "zsize": 16,
  "slices": [
    [
      "                ",
      "                ",
      "                ",
      "                ",
      "                ",
      "                ",
      "                ",
      "                ",
      "                ",
      "                ",
      "                ",
      "                ",
      "            xxx ",
      "            xxx ",
      "            xxx ",
      "                "
    ],
    [
      "xxxxxxxxxxxxxxxx",
      "xxxxxxxxxxxxxxxx",
      "xxxxxxxxxxxxxxxx",
      "xxxxxxxxxxxxxxxx",
      "xxxxxxxxxxxxxxxx",
      "xxxxxxxxxxxxxxxx",
      "xxxxxxxxxxxxxxxx",
      "xxxxxxxxxxxxxxxx",
      "xxxxxxxxxxxxxxxx",
      "xxxxxxxxxxxxxxxx",
      "xxxxxxxxxxxxxxxx",
      "xxxxxxxxxxxxxxxx",
      "xxxxxxxxxxxxxxxx",
      "xxxxxxxxxxxxxxxx",
      "xxxxxxxxxxxxxxxx",
      "xxxxxxxxxxxxxxxx"
    ],
    [
      "    D         D ",
      "    D         D ",
      "  C D     C   D ",
      "    D         D ",
      "    D         u ",
      "    D         D:",
      "    D    4   CD:",
      "    D C       D ",
      "    D         D:",
      "    D         D:",
      "  C D         D ",
      "    D    4   CDp",
      "    D         Dp",
      "    D     C   D ",
      "DDDDuDDDDDDDDDu ",
      "     :: :: ll   "
    ],
    [
      "    :         D ",
      "    D         D ",
      "    :         D ",
      "    D         D ",
      "    :         u ",
      "    D         w:",
      "    :         w:",
      "    D         D ",
      "    :         w:",
      "    D         w:",
      "    :         D ",
      "    D         w ",
      "    :         w ",
      "    D         D ",
      "DDDDuwwDwwDwwDu ",
      "     :: ::      "
    ],
    [
      "    D         D ",
      "    D         D ",
      "    D         D ",
      "    D         D ",
      "    D         u ",
      "    D         D:",
      "    D         D:",
      "    D         D ",
      "    D         D:",
      "    D         D:",
      "    D         D ",
      "    D         D8",
      "    D         D8",
      "    D         D ",
      "DDDDuDDDDDDDDDu ",
      "     :: :: 55   "
    ],
    [
      "xxxxxxxxxxxxxxxx",
      "xxxxxxxxxxxxxxxx",
      "xxxxxxxxxxxxxxxx",
      "xxxxxxxxxxxxxxxx",
      "xxxxxxxxxxxxxxxx",
      "xxxxxxxxxxxxxxxx",
      "xxxxxxxxxxxxxxxx",
      "xxxxxxxxxxxxxxxx",
      "xxxxxxxxxxxxxxxx",
      "xxxxxxxxxxxxxxxx",
      "xxxxxxxxxxxxxxxx",
      "xxxxxxxxxxxxxxxx",
      "xxxxxxxxxxxxxxxx",
      "xxxxxxxxxxxxxxxx",
      "xxxxxxxxxxxxxxxx",
      "xxxxxxxxxxxxxxxx"
    ],
    [
      " =u=D         D ",
      " ===D         D ",
      " ===us   2    u ",
      " ===D    2    D ",
      " =u=D         D ",
      " =u=D         D ",
      " ===D         D ",
      " ===uDDDDuD  Du ",
      "                ",
      "                ",
      "          ===== ",
      " & &            ",
      "          ===== ",
      " & & 2          ",
      "          ===== ",
      "                "
    ],
    [
      "    &         & ",
      "    2         2 ",
      "    us        u ",
      "    2         2 ",
      "    &         & ",
      "    &         & ",
      "    2         2 ",
      "    u2::2u2  2u ",
      "                ",
      "                ",
      "                ",
      " = =            ",
      "                ",
      " = = 2          ",
      "                ",
      "                "
    ],
    [
      "    D         D ",
      "    D         D ",
      "    u         u ",
      "    D         D ",
      "    D         D ",
      "    D         D ",
      "    D         D ",
      "    uDDDDuDDDDu ",
      "                ",
      "                ",
      "                ",
      "                ",
      "                ",
      "     2          ",
      "                ",
      "                "
    ],
    [
      "    =========== ",
      "    =========== ",
      "    =========== ",
      "    =uuuu====== ",
      "    =u::u====== ",
      "    =u::u====== ",
      "    =uuuu====== ",
      "    =========== ",
      "                ",
      "                ",
      "                ",
      "                ",
      "                ",
      "     2          ",
      "                ",
      "                "
    ],
    [
      "                ",
      "                ",
      "                ",
      "     2  2       ",
      "                ",
      "                ",
      "     2  2       ",
      "                ",
      "                ",
      "                ",
      "                ",
      "                ",
      "                ",
      "     2          ",
      "                ",
      "                "
    ],
    [
      "                ",
      "                ",
      "                ",
      "     g  g       ",
      "                ",
      "                ",
      "     g  g       ",
      "                ",
      "                ",
      "                ",
      "                ",
      "                ",
      "     :          ",
      "    :2:         ",
      "     :          ",
      "                "
    ],
    [
      "                ",
      "                ",
      "                ",
      "                ",
      "                ",
      "                ",
      "                ",
      "                ",
      "                ",
      "                ",
      "                ",
      "                ",
      "     :          ",
      "    :2:         ",
      "     :          ",
      "                "
    ],
    [
      "                ",
      "                ",
      "                ",
      "                ",
      "                ",
      "                ",
      "                ",
      "                ",
      "                ",
      "                ",
      "                ",
      "                ",
      "     :          ",
      "    : :         ",
      "     :          ",
      "                "
    ],
    [
      "                ",
      "                ",
      "                ",
      "                ",
      "                ",
      "                ",
      "                ",
      "                ",
      "                ",
      "                ",
      "                ",
      "                ",
      "     g          ",
      "    g g         ",
      "     g          ",
      "                "
    ],
    [
      "                ",
      "                ",
      "                ",
      "                ",
      "                ",
      "                ",
      "                ",
      "                ",
      "                ",
      "                ",
      "                ",
      "                ",
      "                ",
      "                ",
      "                ",
      "                "
    ],
    [
      "                ",
      "                ",
      "                ",
      "                ",
      "                ",
      "                ",
      "                ",
      "                ",
      "                ",
      "                ",
      "                ",
      "                ",
      "                ",
      "                ",
      "                ",
      "                "
    ],
    [
      "                ",
      "                ",
      "                ",
      "                ",
      "                ",
      "                ",
      "                ",
      "                ",
      "                ",
      "                ",
      "                ",
      "                ",
      "                ",
      "                ",
      "                ",
      "                "
    ],
    [
      "                ",
      "                ",
      "                ",
      "                ",
      "                ",
      "                ",
      "                ",
      "                ",
      "                ",
      "                ",
      "                ",
      "                ",
      "                ",
      "                ",
      "                ",
      "                "
    ],
    [
      "                ",
      "                ",
      "                ",
      "                ",
      "                ",
      "                ",
      "                ",
      "                ",
      "                ",
      "                ",
      "                ",
      "                ",
      "                ",
      "                ",
      "                ",
      "                "
    ],
    [
      "                ",
      "                ",
      "                ",
      "                ",
      "                ",
      "                ",
      "                ",
      "                ",
      "                ",
      "                ",
      "                ",
      "                ",
      "                ",
      "                ",
      "                ",
      "                "
    ],
    [
      "                ",
      "                ",
      "                ",
      "                ",
      "                ",
      "                ",
      "                ",
      "                ",
      "                ",
      "                ",
      "                ",
      "                ",
      "                ",
      "                ",
      "                ",
      "                "
    ]
  ]
}
