{
  "xsize": 16,
  "zsize": 16,
  "refpalette": "oilrig",
  "slices": [
    [
      "                ",
      " xxx            ",
      " xxx            ",
      " xxx            ",
      "                ",
      "                ",
      "                ",
      "                ",
      "                ",
      "                ",
      "                ",
      "                ",
      "                ",
      "                ",
      "                ",
      "                "
    ],
    [
      "xxxxxxxxxxxxxxxx",
      "xxxxxxxxxxxxxxxx",
      "xxxxxxxxxxxxxxxx",
      "xxxxxxxxxxxxxxxx",
      "xxxxxxxxxxxxxxxx",
      "xxxxxxxxxxxxxxxx",
      "xxxxxxxxxxxxxxxx",
      "xxxxxxxxxxxxxxxx",
      "xxxxxxxxxxxxxxxx",
      "xxxxxxxxxxxxxxxx",
      "xxxxxxxxxxxxxxxx",
      "xxxxxxxxxxxxxxxx",
      "xxxxxxxxxxxxxxxx",
      "xxxxxxxxxxxxxxxx",
      "xxxxxxxxxxxxxxxx",
      "xxxxxxxxxxxxxxxx"
    ],
    [
      "   oo :: ::     ",
      " uDDDDDDDDDuDDDD",
      " D  4     CD    ",
      "iD  e      D    ",
      "iD  e   C  D    ",
      " D         D    ",
      ":D         u    ",
      ":D              ",
      " D   C          ",
      ":D              ",
      ":D            C ",
      " uDDDDu    u    ",
      " D  4           ",
      " D              ",
      " D      C       ",
      " D              "
    ],
    [
      "      :: ::     ",
      " uDwwDwwDwwuDDDD",
      " D         D    ",
      " w   e     D    ",
      " w   f     D    ",
      " D         D    ",
      ":w         u    ",
      ":w              ",
      " D              ",
      ":w              ",
      ":w              ",
      " uDDDDu    u    ",
      " D              ",
      " D              ",
      " D              ",
      " D              "
    ],
    [
      "   77 :: ::     ",
      " uDDDDDDDDDuDDDD",
      " D         D    ",
      "6D    e    D    ",
      "6D    e    D    ",
      " D         D    ",
      ":D         u    ",
      ":D              ",
      " D              ",
      ":D              ",
      ":D              ",
      " uDDDDu    u    ",
      " D              ",
      " D              ",
      " D              ",
      " D              "
    ],
    [
      "xxxxxxxxxxxxxxxx",
      "xxxxxxxxxxxxxxxx",
      "xxxxxxxxxxxxxxxx",
      "xxxx   fxxxxxxxx",
      "xxxx   exxxxxxxx",
      "xxxxxxxxxxxxxxxx",
      "xxxxxxxxxxxxxxxx",
      "xxxxxxxxxxxxxxxx",
      "xxxxxxxxxxxxxxxx",
      "xxxxxxxxxxxxxxxx",
      "xxxxxxxxxxxxxxxx",
      "xxxxxxxxxxxxxxxx",
      "xxxxxxxxxxxxxxxx",
      "xxxxxxxxxxxxxxxx",
      "xxxxxxxxxxxxxxxx",
      "xxxxxxxxxxxxxxxx"
    ],
    [
      "g:    g    :    ",
      ":u7777u7777u:= =",
      " 6         8 k k",
      " 6         8 k k",
      " 6         8 k k",
      " 6         8 k k",
      "gu         u k k",
      " 6         8 k k",
      " 6         8 k k",
      " 6         8 k k",
      " 6         8 k k",
      ":u555D_D555u k k",
      " :     :   : k k",
      "       :   : k k",
      "       :   : = =",
      "       u:::u    "
    ],
    [
      " :         :    ",
      ":u7777u7777u:   ",
      " 6         8    ",
      " 6         8    ",
      " 6         8    ",
      " 6         8    ",
      " u         u    ",
      " 6         8    ",
      " 6         8    ",
      " 6         8    ",
      " 6         8    ",
      ":u555D-D555u    ",
      " :              ",
      "                ",
      "                ",
      "       u   u    "
    ],
    [
      "                ",
      " uDDDDuDDDDu    ",
      " D         :    ",
      " D         :    ",
      " D         :    ",
      " D         :    ",
      " u         u    ",
      " D         :    ",
      " D         :    ",
      " D         :    ",
      " D    r    :    ",
      " u::::u::::u    ",
      "      L         ",
      "                ",
      "                ",
      "       g   g    "
    ],
    [
      "                ",
      " ===========    ",
      " =======uuu=    ",
      " =======u=u=    ",
      " =======uuu=    ",
      " ===========    ",
      " ===========    ",
      " ===========    ",
      " ===========    ",
      " ===========    ",
      " ===========    ",
      " ===========    ",
      "                ",
      "                ",
      "                ",
      "                "
    ],
    [
      "                ",
      "                ",
      "        :::     ",
      "        : :     ",
      "        :::     ",
      "                ",
      "                ",
      "                ",
      "                ",
      "                ",
      "                ",
      "                ",
      "                ",
      "                ",
      "                ",
      "                "
    ],
    [
      "                ",
      "                ",
      "        :::     ",
      "        : :     ",
      "        :::     ",
      "                ",
      "                ",
      "                ",
      "                ",
      "                ",
      "                ",
      "                ",
      "                ",
      "                ",
      "                ",
      "                "
    ],
    [
      "                ",
      "                ",
      "        g g     ",
      "                ",
      "        g g     ",
      "                ",
      "                ",
      "                ",
      "                ",
      "                ",
      "                ",
      "                ",
      "                ",
      "                ",
      "                ",
      "                "
    ],
    [
      "                ",
      "                ",
      "                ",
      "                ",
      "                ",
      "                ",
      "                ",
      "                ",
      "                ",
      "                ",
      "                ",
      "                ",
      "                ",
      "                ",
      "                ",
      "                "
    ],
    [
      "                ",
      "                ",
      "                ",
      "                ",
      "                ",
      "                ",
      "                ",
      "                ",
      "                ",
      "                ",
      "                ",
      "                ",
      "                ",
      "                ",
      "                ",
      "                "
    ],
    [
      "                ",
      "                ",
      "                ",
      "                ",
      "                ",
      "                ",
      "                ",
      "                ",
      "                ",
      "                ",
      "                ",
      "                ",
      "                ",
      "                ",
      "                ",
      "                "
    ],
    [
      "                ",
      "                ",
      "                ",
      "                ",
      "                ",
      "                ",
      "                ",
      "                ",
      "                ",
      "                ",
      "                ",
      "                ",
      "                ",
      "                ",
      "                ",
      "                "
    ],
    [
      "                ",
      "                ",
      "                ",
      "                ",
      "                ",
      "                ",
      "                ",
      "                ",
      "                ",
      "                ",
      "                ",
      "                ",
      "                ",
      "                ",
      "                ",
      "                "
    ],
    [
      "                ",
      "                ",
      "                ",
      "                ",
      "                ",
      "                ",
      "                ",
      "                ",
      "                ",
      "                ",
      "                ",
      "                ",
      "                ",
      "                ",
      "                ",
      "                "
    ],
    [
      "                ",
      "                ",
      "                ",
      "                ",
      "                ",
      "                ",
      "                ",
      "                ",
      "                ",
      "                ",
      "                ",
      "                ",
      "                ",
      "                ",
      "                ",
      "                "
    ],
    [
      "                ",
      "                ",
      "                ",
      "                ",
      "                ",
      "                ",
      "                ",
      "                ",
      "                ",
      "                ",
      "                ",
      "                ",
      "                ",
      "                ",
      "                ",
      "                "
    ]
  ]
}
