{
  "xsize": 16,
  "zsize": 16,
  "refpalette": "oilrig",
  "slices": [
    [
      "                ",
      "                ",
      "                ",
      "                ",
      "                ",
      "                ",
      "                ",
      "                ",
      "                ",
      "                ",
      "                ",
      "                ",
      " xxx            ",
      " xxx            ",
      " xxx            ",
      "                "
    ],
    [
      "xxxxxxxxxxxxxxxx",
      "xxxxxxxxxxxxxxxx",
      "xxxxxxxxxxxxxxxx",
      "xxxxxxxxxxxxxxxx",
      "xxxxxxxxxxxxxxxx",
      "xxxxxxxxxxxxxxxx",
      "xxxxxxxxxxxxxxxx",
      "xxxxxxxxxxxxxxxx",
      "xxxxxxxxxxxxxxxx",
      "xxxxxxxxxxxxxxxx",
      "xxxxxxxxxxxxxxxx",
      "xxxxxxxxxxxxxxxx",
      "xxxxxxxxxxxxxxxx",
      "xxxxxxxxxxxxxxxx",
      "xxxxxxxxxxxxxxxx",
      "xxxxxxxxxxxxxxxx"
    ],
    [
      " D           qqq",
      " D       C   qqq",
      " Dj          qqq",
      " D     m        ",
      " uDDDDDnD::D    ",
      ":D     m   D    ",
      ":D  C      Ds   ",
      " D         DE   ",
      ":D      EE Ds   ",
      ":D      EE D    ",
      " DC        D  C ",
      "iD        ND    ",
      "iD         D    ",
      " D      C  D    ",
      " uDDDDDDDDDuDDDD",
      "   ll :: ::     "
    ],
    [
      " D           qqq",
      " D           q4q",
      " Dj          qqq",
      " D              ",
      " uDDDDDOD::D    ",
      ":w         D    ",
      ":w         D    ",
      " D         DP   ",
      ":w      PP D    ",
      ":w      PP D    ",
      " D         D    ",
      " w        ND    ",
      " w         D    ",
      " D        4D    ",
      " uDwwDwwDwwuDDDD",
      "      :: ::     "
    ],
    [
      " D           qqq",
      " D           qqq",
      " Dj          qqq",
      " D              ",
      " uDDDDDDD::D    ",
      ":D         D    ",
      ":D         D    ",
      " D         D    ",
      ":D         D    ",
      ":D         D    ",
      " D         D    ",
      "6D         D    ",
      "6D         D    ",
      " D         D    ",
      " uDDDDDDDDDuDDDD",
      "   55 :: ::     "
    ],
    [
      "xxxxxxxxxxxxxxxx",
      "xxxxxxxxxxxxxxxx",
      "xxjxxxxxxxxxxxxx",
      "xxxxxxxxxxxxxxxx",
      "xxxxxxxxxxxxxxxx",
      "xxxxxxxxxxxxxxxx",
      "xxxxxxxxxxxxxxxx",
      "xxxxxxxxxxxxxxxx",
      "xxxxxxxxxxxxxxxx",
      "xxxxxxxxxxxxxxxx",
      "xxxxxxxxxxxxxxxx",
      "xxxxxxxxxxxxxxxx",
      "xxxxxxxxxxxxxxxx",
      "xxxxxxxxxxxxxxxx",
      "xxxxxxxxxxxxxxxx",
      "xxxxxxxxxxxxxxxx"
    ],
    [
      "                ",
      " ::::           ",
      " :Vm            ",
      " ::::   u^u^u^u ",
      " =======^     ^ ",
      "       =u III u ",
      "       2^ IJI ^ ",
      "       =u III u ",
      " =======^     ^ ",
      "        u^u^u^u ",
      "                ",
      "                ",
      " u3u u3u u3u    ",
      " 3M3 3M3 3M3    ",
      " u3u u3u u3u    ",
      "                "
    ],
    [
      "                ",
      "                ",
      "                ",
      "        u^u^u^u ",
      "        ^     ^ ",
      "        u III u ",
      "       2^ IJI ^ ",
      "        u III u ",
      "        ^     ^ ",
      "        u^u^u^u ",
      "                ",
      "                ",
      " u2u u2u u2u    ",
      " 2M2 2M2 2M2    ",
      " u2u u2u u2u    ",
      "                "
    ],
    [
      "                ",
      "                ",
      "                ",
      "        u^u^u^u ",
      "        ^     ^ ",
      "        u III u ",
      "       2^ IJI ^ ",
      "        u III u ",
      "        ^     ^ ",
      "        u^u^u^u ",
      "                ",
      "                ",
      " === === ===    ",
      " =0= =0= =0=    ",
      " === === ===    ",
      "                "
    ],
    [
      "                ",
      "                ",
      "                ",
      "        000[[00 ",
      "        0     0 ",
      "      ^^u III [ ",
      "  3   ^2^ IJI 0 ",
      "      ^^u III 0 ",
      "        0     0 ",
      "        00000[0 ",
      "                ",
      "                ",
      "                ",
      "                ",
      "                ",
      "                "
    ],
    [
      "                ",
      "                ",
      "                ",
      "        u^u^u^u ",
      "        ^     ^ ",
      "      w&w III u ",
      "  :   & & IJI ^ ",
      "      w&w III u ",
      "        ^     ^ ",
      "        u^u^u^u ",
      "                ",
      "                ",
      "                ",
      "                ",
      "                ",
      "                "
    ],
    [
      "                ",
      "                ",
      "                ",
      "        u^u^u^u ",
      "        ^     ^ ",
      "      ==u III u ",
      "  :   =2u IJI ^ ",
      "      ==u III u ",
      "        ^     ^ ",
      "        u^u^u^u ",
      "                ",
      "                ",
      "                ",
      "                ",
      "                ",
      "                "
    ],
    [
      "                ",
      "                ",
      "                ",
      "         :   :  ",
      "        ::::::: ",
      "         :000:  ",
      "  :::::2|:000:  ",
      "         :000:  ",
      "        ::::::: ",
      "         :   :  ",
      "                ",
      "                ",
      "                ",
      "                ",
      "                ",
      "                "
    ],
    [
      "                ",
      "                ",
      "                ",
      "                ",
      "                ",
      "           3    ",
      "          3 3   ",
      "           3    ",
      "                ",
      "                ",
      "                ",
      "                ",
      "                ",
      "                ",
      "                ",
      "                "
    ],
    [
      "                ",
      "                ",
      "                ",
      "                ",
      "                ",
      "           &    ",
      "          & &   ",
      "           &    ",
      "                ",
      "                ",
      "                ",
      "                ",
      "                ",
      "                ",
      "                ",
      "                "
    ],
    [
      "                ",
      "                ",
      "                ",
      "                ",
      "                ",
      "           3    ",
      "          3 3   ",
      "           3    ",
      "                ",
      "                ",
      "                ",
      "                ",
      "                ",
      "                ",
      "                ",
      "                "
    ],
    [
      "                ",
      "                ",
      "                ",
      "                ",
      "                ",
      "           :    ",
      "          :u:   ",
      "           :    ",
      "                ",
      "                ",
      "                ",
      "                ",
      "                ",
      "                ",
      "                ",
      "                "
    ],
    [
      "                ",
      "                ",
      "                ",
      "                ",
      "                ",
      "                ",
      "           :    ",
      "                ",
      "                ",
      "                ",
      "                ",
      "                ",
      "                ",
      "                ",
      "                ",
      "                "
    ],
    [
      "                ",
      "                ",
      "                ",
      "                ",
      "                ",
      "                ",
      "                ",
      "                ",
      "                ",
      "                ",
      "                ",
      "                ",
      "                ",
      "                ",
      "                ",
      "                "
    ],
    [
      "                ",
      "                ",
      "                ",
      "                ",
      "                ",
      "                ",
      "                ",
      "                ",
      "                ",
      "                ",
      "                ",
      "                ",
      "                ",
      "                ",
      "                ",
      "                "
    ],
    [
      "                ",
      "                ",
      "                ",
      "                ",
      "                ",
      "                ",
      "                ",
      "                ",
      "                ",
      "                ",
      "                ",
      "                ",
      "                ",
      "                ",
      "                ",
      "                "
    ],
    [
      "                ",
      "                ",
      "                ",
      "                ",
      "                ",
      "                ",
      "                ",
      "                ",
      "                ",
      "                ",
      "                ",
      "                ",
      "                ",
      "                ",
      "                ",
      "                "
    ]
  ]
}
