{
  "xsize": 16,
  "zsize": 16,
  "refpalette": "oilrig",
  "slices": [
    [
      "                ",
      "            xxx ",
      "            xxx ",
      "            xxx ",
      "                ",
      "                ",
      "                ",
      "                ",
      "                ",
      "                ",
      "                ",
      "                ",
      "                ",
      "                ",
      "                ",
      "                "
    ],
    [
      "xxxxxxxxxxxxxxxx",
      "xxxxxxxxxxxxxxxx",
      "xxxxxxxxxxxxxxxx",
      "xxxxxxxxxxxxxxxx",
      "xxxxxxxxxxxxxxxx",
      "xxxxxxxxxxxxxxxx",
      "xxxxxxxxxxxxxxxx",
      "xxxxxxxxxxxxxxxx",
      "xxxxxxxxxxxxxxxx",
      "xxxxxxxxxxxxxxxx",
      "xxxxxxxxxxxxxxxx",
      "xxxxxxxxxxxxxxxx",
      "xxxxxxxxxxxxxxxx",
      "xxxxxxxxxxxxxxxx",
      "xxxxxxxxxxxxxxxx",
      "xxxxxxxxxxxxxxxx"
    ],
    [
      "     :: :: oo   ",
      "DDDDuDDDDDDDDDu ",
      "    D         D ",
      "  C D  C      Dp",
      "    D         Dp",
      "    D         D ",
      "    D         D:",
      "    :     C   D:",
      "              D ",
      "              D:",
      "    :         D:",
      "    D         u ",
      "  C D         D ",
      "    D         D ",
      "    D      C  D ",
      "    D         D "
    ],
    [
      "     :: :: oo   ",
      "DDDDuDDDDDDDDDu ",
      "    D         D ",
      "    :         w ",
      "    D         w ",
      "    :         D ",
      "    D         w:",
      "    :         w:",
      "              D ",
      "              w:",
      "    :         w:",
      "    D         u ",
      "    :         D ",
      "    D         D ",
      "    :         D ",
      "    D         D "
    ],
    [
      "     :: :: 77   ",
      "DDDDuDDDDDDDDDu ",
      "    D         D ",
      "    D         D8",
      "    D         D8",
      "    D         D ",
      "    D         D:",
      "    :         D:",
      "              D ",
      "              D:",
      "    :         D:",
      "    D         u ",
      "    D         D ",
      "    D         D ",
      "    D         D ",
      "    D         D "
    ],
    [
      "xxxxxxxxxxxxxxxx",
      "xxxxxxxxxxxxxxxx",
      "xxxxxxxxxxxxxxxx",
      "xxxxxxxxxxxxxxxx",
      "xxxxxxxxxxxxxxxx",
      "xxxxxxxxxxxxxxxx",
      "xxxxxxxxxxxxxxxx",
      "xxxxxxxxxxxxxxxx",
      "xxxxxxxxxxxxxxxx",
      "xxxxxxxxxxxxxxxx",
      "xxxxxxxxxxxxxxxx",
      "xxxxxxxxxxxxxxxx",
      "xxxxxxxxxxxxxxxx",
      "xxxxxxxxxxxxxxxx",
      "xxxxxxxxxxxxxxxx",
      "xxxxxxxxxxxxxxxx"
    ],
    [
      "                ",
      "                ",
      "        2222    ",
      "    2:::2  2    ",
      "        2222    ",
      "                ",
      "                ",
      "       m        ",
      " ===uDDnDuDDDDu ",
      " ===D  m = UU D ",
      " =u=D    =    D ",
      " =u=D    =    D ",
      " ===D    =   CD ",
      " ===u    =====u ",
      " ===D        4D ",
      " =u=D         D "
    ],
    [
      "                ",
      "                ",
      "        2332    ",
      "    2:::2  2    ",
      "        2332    ",
      "                ",
      "                ",
      "                ",
      "    u22O2u2222u ",
      "    2      UU 2 ",
      "    &         & ",
      "    &         & ",
      "    2         2 ",
      "    u         u ",
      "    2         2 ",
      "    &         & "
    ],
    [
      "                ",
      "                ",
      "        2&&2    ",
      "    2   2  2    ",
      "        2&&2    ",
      "                ",
      "                ",
      "                ",
      "    uDDDDuDDDDu ",
      "    D         D ",
      "    D         D ",
      "    D         D ",
      "    D         D ",
      "    u         u ",
      "    D         D ",
      "    D         D "
    ],
    [
      "                ",
      "                ",
      "        2222    ",
      "    g   2222    ",
      "        2222    ",
      "                ",
      "                ",
      "                ",
      "    =========== ",
      "    =========u= ",
      "    =========== ",
      "    =========== ",
      "    =========== ",
      "    =========== ",
      "    =========== ",
      "    =========== "
    ],
    [
      "                ",
      "                ",
      "                ",
      "                ",
      "                ",
      "                ",
      "                ",
      "                ",
      "                ",
      "             :  ",
      "                ",
      "                ",
      "                ",
      "                ",
      "                ",
      "                "
    ],
    [
      "                ",
      "                ",
      "                ",
      "                ",
      "                ",
      "                ",
      "                ",
      "                ",
      "                ",
      "             :  ",
      "                ",
      "                ",
      "                ",
      "                ",
      "                ",
      "                "
    ],
    [
      "                ",
      "                ",
      "                ",
      "                ",
      "                ",
      "                ",
      "                ",
      "                ",
      "             :  ",
      "            ::: ",
      "             :  ",
      "                ",
      "                ",
      "                ",
      "                ",
      "                "
    ],
    [
      "                ",
      "                ",
      "                ",
      "                ",
      "                ",
      "                ",
      "                ",
      "                ",
      "                ",
      "             g  ",
      "                ",
      "                ",
      "                ",
      "                ",
      "                ",
      "                "
    ],
    [
      "                ",
      "                ",
      "                ",
      "                ",
      "                ",
      "                ",
      "                ",
      "                ",
      "                ",
      "                ",
      "                ",
      "                ",
      "                ",
      "                ",
      "                ",
      "                "
    ],
    [
      "                ",
      "                ",
      "                ",
      "                ",
      "                ",
      "                ",
      "                ",
      "                ",
      "                ",
      "                ",
      "                ",
      "                ",
      "                ",
      "                ",
      "                ",
      "                "
    ],
    [
      "                ",
      "                ",
      "                ",
      "                ",
      "                ",
      "                ",
      "                ",
      "                ",
      "                ",
      "                ",
      "                ",
      "                ",
      "                ",
      "                ",
      "                ",
      "                "
    ],
    [
      "                ",
      "                ",
      "                ",
      "                ",
      "                ",
      "                ",
      "                ",
      "                ",
      "                ",
      "                ",
      "                ",
      "                ",
      "                ",
      "                ",
      "                ",
      "                "
    ],
    [
      "                ",
      "                ",
      "                ",
      "                ",
      "                ",
      "                ",
      "                ",
      "                ",
      "                ",
      "                ",
      "                ",
      "                ",
      "                ",
      "                ",
      "                ",
      "                "
    ],
    [
      "                ",
      "                ",
      "                ",
      "                ",
      "                ",
      "                ",
      "                ",
      "                ",
      "                ",
      "                ",
      "                ",
      "                ",
      "                ",
      "                ",
      "                ",
      "                "
    ],
    [
      "                ",
      "                ",
      "                ",
      "                ",
      "                ",
      "                ",
      "                ",
      "                ",
      "                ",
      "                ",
      "                ",
      "                ",
      "                ",
      "                ",
      "                ",
      "                "
    ],
    [
      "                ",
      "                ",
      "                ",
      "                ",
      "                ",
      "                ",
      "                ",
      "                ",
      "                ",
      "                ",
      "                ",
      "                ",
      "                ",
      "                ",
      "                ",
      "                "
    ]
  ]
}
