{
  "xsize": 16,
  "zsize": 16,
  "slices": [
    [
      "SQQSSQQSSQQSSQQ#",
      "QSSQQSSQQSSQQSS#",
      "QSSQQSSQQSSQQSS#",
      "SQQSSQQSSQQSSQQ#",
      "SQQSSQQSSQQSSQQ#",
      "QSSQQSSQQSSQQSS#",
      "QSSQQSSQQSSQQSS#",
      "SQQSSQQSSQQSSQQ#",
      "SQQSSQQSSQQSSQQ#",
      "QSSQQSSQQSSQQSS#",
      "QSSQQSSQQSSQQSS#",
      "SQQSSQQSSQQSSQQ#",
      "SQQSSQQSSQQSSQQ#",
      "QSSQQSSQQSSQQSS#",
      "QSSQQSSQQSSQQSS#",
      "################"
    ],
    [
      "               #",
      "   C           #",
      "              ##",
      "              # ",
      "              # ",
      "         C    # ",
      "              ##",
      "               #",
      "               #",
      "              ##",
      "              # ",
      "     C        # ",
      "              # ",
      "              ##",
      "  #####  #######",
      "###   ####   ###"
    ],
    [
      "               a",
      "               a",
      "              ##",
      "              a ",
      "              a ",
      "              a ",
      "              ##",
      "               a",
      "               a",
      "              ##",
      "              a ",
      "              a ",
      "              a ",
      "              ##",
      "  #aaa#  #aaa###",
      "###   #aa#   ###"
    ],
    [
      "               a",
      "               a",
      "              ##",
      "              a ",
      "              a ",
      "              a ",
      "             T##",
      "               a",
      "               a",
      "             T##",
      "              a ",
      "              a ",
      "              a ",
      "      T  T    ##",
      "  #aaa#  #aaa###",
      "###   #aa#   ###"
    ],
    [
      "               a",
      "               a",
      "              ##",
      "              a ",
      "              a ",
      "              a ",
      "              ##",
      "               a",
      "               a",
      "              ##",
      "              a ",
      "              a ",
      "              a ",
      "              ##",
      "  #aaa#  #aaa###",
      "###   #aa#   ###"
    ],
    [
      "               a",
      "               a",
      "              ##",
      "              a ",
      "              a ",
      "              a ",
      "              ##",
      "               a",
      "               a",
      "              ##",
      "              a ",
      "              a ",
      "              a ",
      "              ##",
      "  #aaa#  #aaa###",
      "###   #aa#   ###"
    ]
  ]
}