{
  "xsize": 16,
  "zsize": 16,
  "slices": [
    [
      "QQQQQQQQQQQQQQQQ",
      "QSSQQSSQQSSQQSSQ",
      "QSSQQSSQQSSQQSSQ",
      "SQQSSQQSSQQSSQQQ",
      "SQQSSQQSSQQSSQQQ",
      "QSSQQSSQQSSQQSSQ",
      "QSSQQSSQQSSQQSSQ",
      "SQQSSQQSSQQSSQQQ",
      "SQQSSQQSSQQSSQQQ",
      "QSSQQSSQQSSQQSSQ",
      "QSSQQSSQQSSQQSSQ",
      "SQQSSQQSSQQSSQQQ",
      "SQQSSQQSSQQSSQQQ",
      "QSSQQSSQQSSQQSSQ",
      "QSSQQSSQQSSQQSSQ",
      "SQQSSQQSSQQSSQQQ"
    ],
    [
      "################",
      ":              #",
      ":   C          #",
      ":              #",
      ":              #",
      ":          C   #",
      ":              #",
      ":              #",
      ":              #",
      ":              #",
      ":    C         #",
      ":              #",
      ":              #",
      ":              #",
      ":           C  #",
      ":              #"
    ],
    [
      "################",
      "               #",
      "               #",
      "               #",
      "               #",
      "               #",
      "               #",
      "               #",
      "               #",
      "               #",
      "               #",
      "               #",
      "               #",
      "               #",
      "               #",
      "               #"
    ],
    [
      "##aa#aa#aa#aa###",
      "       T       #",
      "               #",
      "               a",
      "               a",
      "               #",
      "               a",
      "               a",
      "              T#",
      "               a",
      "               a",
      "               #",
      "               a",
      "               a",
      "               #",
      "               a"
    ],
    [
      "################",
      "               #",
      "               #",
      "               #",
      "               #",
      "               #",
      "               #",
      "               #",
      "               #",
      "               #",
      "               #",
      "               #",
      "               #",
      "               #",
      "               #",
      "               #"
    ],
    [
      "################",
      "################",
      "################",
      "################",
      "################",
      "################",
      "################",
      "################",
      "################",
      "################",
      "################",
      "################",
      "################",
      "################",
      "################",
      "################"
    ]
  ]
}