{
  "meta": [
    {
      "key": "dontconnect",
      "boolean": true
    }
  ],
  "xsize": 16,
  "zsize": 16,
  "slices": [
    [
      " #######))))####",
      " #SQQSSQQSSQQSSQ",
      " #QSSQQSSQQSSQQS",
      " #QSSQQSSQQSSQQS",
      " #SQQSSQQSSQQSSQ",
      " #SQQSSQQSSQQSSQ",
      " #QSSQQSSQQSSQQS",
      " #QSSQQSSQQSSQQS",
      " #SQQSSQQSSQQSSQ",
      " #SQQSSQQSSQQSSQ",
      " #QSSQQSSQQSSQQS",
      " #QSSQQSSQQSSQQS",
      " #SQQSSQQSSQQSSQ",
      " #SQQSSQQSSQQSSQ",
      " ###############",
      "                "
    ],
    [
      " ::::::w    w:::",
      " :              ",
      " :           C  ",
      " :              ",
      " :  C           ",
      " :              ",
      " :              ",
      " :              ",
      " :           C  ",
      " :              ",
      " :   C          ",
      " :              ",
      " :              ",
      " :          C   ",
      " w::::::::::::::",
      "                "
    ],
    [
      "       T    T   ",
      "                ",
      "                ",
      "                ",
      "                ",
      "                ",
      "                ",
      "                ",
      "                ",
      "                ",
      "                ",
      "                ",
      "                ",
      "                ",
      " w              ",
      "                "
    ],
    [
      "                ",
      "                ",
      "                ",
      "                ",
      "                ",
      "                ",
      "                ",
      "                ",
      "                ",
      "                ",
      "                ",
      "                ",
      "                ",
      "                ",
      " w              ",
      "                "
    ],
    [
      "                ",
      "                ",
      "                ",
      "                ",
      "                ",
      "                ",
      "                ",
      "                ",
      "                ",
      "                ",
      "                ",
      "                ",
      "                ",
      "                ",
      " #              ",
      "                "
    ],
    [
      "################",
      "################",
      "################",
      "################",
      "################",
      "################",
      "################",
      "################",
      "################",
      "################",
      "################",
      "################",
      "################",
      "################",
      "################",
      "################"
    ]
  ]
}