{
  "xsize": 16,
  "zsize": 16,
  "slices": [
    [
      "################",
      "QSSQQSSQQSSQQSS#",
      "QSSQQSSQQSSQQSS#",
      "SQQSSQQSSQQSSQQ#",
      "SQQSSQQSSQQSSQQ#",
      "QSSQQSSQQSSQQSS#",
      "QSSQQSSQQSSQQSS#",
      "SQQSSQQSSQQSSQQ#",
      "SQQSSQQSSQQSSQQ#",
      "QSSQQSSQQSSQQSS#",
      "QSSQQSSQQSSQQSS#",
      "SQQSSQQSSQQSSQQ#",
      "SQQSSQQSSQQSSQQ#",
      "QSSQQSSQQSSQQSS#",
      "QSSQQSSQQSSQQSS#",
      "SQQSSQQSSQQSSQQ#"
    ],
    [
      "################",
      "               #",
      "   C           #",
      "               #",
      "               #",
      "               #",
      "               #",
      "          C    #",
      "               #",
      "               #",
      "               #",
      "               #",
      "               #",
      "     C         #",
      "               #",
      "               #"
    ],
    [
      "################",
      "               #",
      "               #",
      "               #",
      "               #",
      "               #",
      "               #",
      "               #",
      "               #",
      "               #",
      "               #",
      "               #",
      "               #",
      "               #",
      "               #",
      "               #"
    ],
    [
      "a#aa#aa#aa#aa###",
      "       T       #",
      "               #",
      "               a",
      "               a",
      "               #",
      "               a",
      "               a",
      "              T#",
      "               a",
      "               a",
      "               #",
      "               a",
      "               a",
      "               #",
      "               a"
    ],
    [
      "################",
      "               #",
      "               #",
      "               #",
      "               #",
      "               #",
      "               #",
      "               #",
      "               #",
      "               #",
      "               #",
      "               #",
      "               #",
      "               #",
      "               #",
      "               #"
    ],
    [
      "################",
      "################",
      "################",
      "################",
      "################",
      "################",
      "################",
      "################",
      "################",
      "################",
      "################",
      "################",
      "################",
      "################",
      "################",
      "################"
    ]
  ]
}