{
  "xsize": 16,
  "zsize": 16,
  "slices": [
    [
      "SQQSSQQSSQQSSQQQ",
      "QSSQQSSQQSSQQSSQ",
      "QSSQQSSQQSSQQSSQ",
      "SQQSSQQSSQQSSQQQ",
      "SQQSSQQSSQQSSQQQ",
      "QSSQQSSQQSSQQSSQ",
      "QSSQQSSQQSSQQSSQ",
      "SQQSSQQSSQQSSQQQ",
      "SQQSSQQSSQQSSQQQ",
      "QSSQQSSQQSSQQSSQ",
      "QSSQQSSQQSSQQSSQ",
      "SQQSSQQSSQQSSQQQ",
      "SQQSSQQSSQQSSQQQ",
      "QSSQQSSQQSSQQSSQ",
      "QSSQQSSQQSSQQSSQ",
      "QQQQQQQQQQQQQQQQ"
    ],
    [
      ":              #",
      "    C          #",
      "               #",
      "               #",
      "           C   #",
      "               #",
      "               #",
      "   C           #",
      "       `))`    #",
      "       `  `    #",
      "       `  `    #",
      ":      `  `    #",
      ":      `  `    #",
      ":      `  `    #",
      ":          C   #",
      "################"
    ],
    [
      "               #",
      "               #",
      "               #",
      "               #",
      "               #",
      "               #",
      "               #",
      "               #",
      "       `  `    #",
      "       `))`    #",
      "       `       #",
      "       `       #",
      "       `       #",
      "       `       #",
      "               #",
      "################"
    ],
    [
      "               a",
      "               #",
      "               a",
      "               a",
      "               #",
      "               a",
      "               a",
      "              T#",
      "       `  `    a",
      "       `  `    a",
      "       `))`    #",
      "       `  `    a",
      "       `  `    a",
      "       `  `    #",
      "       T       #",
      "##aa#aa#aa#aa###"
    ],
    [
      "               #",
      "               #",
      "               #",
      "               #",
      "               #",
      "               #",
      "               #",
      "               #",
      "       `  `    #",
      "       `  `    #",
      "       `  `    #",
      "       `))`    #",
      "       `  `    #",
      "       `  `    #",
      "               #",
      "################"
    ],
    [
      "################",
      "################",
      "################",
      "################",
      "################",
      "################",
      "################",
      "################",
      "########  ######",
      "########  ######",
      "########  ######",
      "########  ######",
      "########))######",
      "################",
      "################",
      "################"
    ]
  ]
}