{
  "xsize": 16,
  "zsize": 16,
  "slices": [
    [
      "SQQSSQQSSQQSSQQ#",
      "QSSQQSSQQSSQQSS#",
      "QSSQQSSQQSSQQSS#",
      "SQQSSQQSSQQSSQQ#",
      "SQQSSQQSSQQSSQQ#",
      "QSSQQSSQQSSQQSS#",
      "QSSQQSSQQSSQQSS#",
      "SQQSSQQSSQQSSQQ#",
      "SQQSSQQS  QSSQQ#",
      "QSSQQSSQ  SQQSS#",
      "QSSQQSSQ  SQQSS#",
      "SQQSSQQS  QSSQQ#",
      "SQQSSQQS  QSSQQ#",
      "QSSQQSSQ))SQQSS#",
      "QSSQQSSQQSSQQSS#",
      "################"
    ],
    [
      "               #",
      "   C           #",
      "               #",
      "               #",
      "           C   #",
      "               #",
      "               #",
      "               #",
      "    C  `))`    #",
      "       `  `    #",
      "       `  `    #",
      "       `  `    #",
      "       `  `    #",
      "       `  `    #",
      "         C     #",
      "################"
    ],
    [
      "               #",
      "               #",
      "               #",
      "               #",
      "               #",
      "               #",
      "               #",
      "               #",
      "       `  `    #",
      "       `))`    #",
      "       `  `    #",
      "       `  `    #",
      "       `  `    #",
      "       `  `    #",
      "               #",
      "################"
    ],
    [
      "               a",
      "               #",
      "               a",
      "               a",
      "               #",
      "               a",
      "               a",
      "              T#",
      "       `  `    a",
      "       `  `    a",
      "       `))`    #",
      "       `  `    a",
      "       `  `    a",
      "       `  `    #",
      "               #",
      "a#aa#aa#aa#aa###"
    ],
    [
      "               #",
      "               #",
      "               #",
      "               #",
      "               #",
      "               #",
      "               #",
      "               #",
      "       `  `    #",
      "       `  `    #",
      "       `  `    #",
      "       `))`    #",
      "       `  `    #",
      "       `  `    #",
      "               #",
      "################"
    ],
    [
      "################",
      "################",
      "################",
      "################",
      "################",
      "################",
      "################",
      "################",
      "########  ######",
      "########  ######",
      "########  ######",
      "########  ######",
      "########))######",
      "################",
      "################",
      "################"
    ]
  ]
}