{
  "xsize": 16,
  "zsize": 16,
  "slices": [
    [
      "################",
      "#SSQQSSQQSSQQSSQ",
      "#SSQQSSQQSSQQSSQ",
      "#QQSSQQSSQQSSQQS",
      "#QQSSQQSSQQSSQQS",
      "#SSQQSSQQSSQQSSQ",
      "#SSQQSSQQSSQQSSQ",
      "#QQSSQQSSQQSSQQS",
      "#QQSSQQSSQQSSQQS",
      "#SSQQSSQQSSQQSSQ",
      "#SSQQSSQQSSQQSSQ",
      "#QQSSQQSSQQSSQQS",
      "#QQSSQQSSQQSSQQS",
      "#SSQQSSQQSSQQSSQ",
      "#SSQQSSQQSSQQSSQ",
      "#QQSSQQSSQQSSQQS"
    ],
    [
      "aaaaaaaaaaaaaaaa",
      "a               ",
      "a  C            ",
      "a            C  ",
      "a               ",
      "a      #))))#   ",
      "a               ",
      "a    C          ",
      "a               ",
      "a      w    w   ",
      "a             C ",
      "a               ",
      "a               ",
      "a     C         ",
      "a               ",
      "a      w    w   "
    ],
    [
      "aaaaaaaaaaaaaaaa",
      "a               ",
      "a               ",
      "a               ",
      "a               ",
      "a      w    w   ",
      "a     T#))))#T  ",
      "a               ",
      "a               ",
      "a      w    w   ",
      "a               ",
      "a               ",
      "a               ",
      "a               ",
      "a               ",
      "a      w    w   "
    ],
    [
      "aaaaaaaaaaaaaaaa",
      "a               ",
      "a               ",
      "a               ",
      "a               ",
      "a               ",
      "a      w    w   ",
      "a      #))))#   ",
      "a               ",
      "a      w    w   ",
      "a               ",
      "a               ",
      "a               ",
      "a               ",
      "a               ",
      "a      w    w   "
    ],
    [
      "aaaaaaaaaaaaaaaa",
      "a               ",
      "a               ",
      "a               ",
      "a               ",
      "a               ",
      "a               ",
      "a      w    w   ",
      "a      #))))#   ",
      "a      w    w   ",
      "a               ",
      "a               ",
      "a               ",
      "a               ",
      "a               ",
      "a      w    w   "
    ],
    [
      "aaaaaaaaaaaaaaaa",
      "a               ",
      "a               ",
      "a               ",
      "a               ",
      "a               ",
      "a               ",
      "a               ",
      "a      w    w   ",
      "a      #))))#   ",
      "a               ",
      "a               ",
      "a               ",
      "a               ",
      "a               ",
      "a      w    w   "
    ]
  ]
}