{
  "xsize": 16,
  "zsize": 16,
  "slices": [
    [
      "################",
      "QSSQQSSQQSSQQSS#",
      "QSSQQSSQQSSQQSS#",
      "SQQSSQQSSQQSSQQ#",
      "SQQSSQQSSQQSSQQ#",
      "QSSQQSSQQSSQQSS#",
      "QSSQQSSQQSSQQSS#",
      "SQQSSQQSSQQSSQQ#",
      "SQQSSQQSSQQSSQQ#",
      "QSSQQSSQQSSQQSS#",
      "QSSQQSSQQSSQQSS#",
      "SQQSSQQSSQQSSQQ#",
      "SQQSSQQSSQQSSQQ#",
      "QSSQQSSQQSSQQSS#",
      "QSSQQSSQQSSQQSS#",
      "SQQSSQQSSQQSSQQ#"
    ],
    [
      "###   ####   ###",
      "# #####  #######",
      "              ##",
      "    C         # ",
      "              # ",
      "              # ",
      "           C  ##",
      "               #",
      "               #",
      "    C         ##",
      "              # ",
      "              # ",
      "              # ",
      "              ##",
      "        C      #",
      "               #"
    ],
    [
      "###   #aa#   ###",
      "# #aaa#  #aaa###",
      "              ##",
      "              a ",
      "              a ",
      "              a ",
      "              ##",
      "               a",
      "               a",
      "              ##",
      "              a ",
      "              a ",
      "              a ",
      "              ##",
      "               a",
      "               a"
    ],
    [
      "###   #aa#   ###",
      "# #aaa#  #aaa###",
      "      T  T    ##",
      "              a ",
      "              a ",
      "              a ",
      "             T##",
      "               a",
      "               a",
      "             T##",
      "              a ",
      "              a ",
      "              a ",
      "              ##",
      "               a",
      "               a"
    ],
    [
      "###   #aa#   ###",
      "# #aaa#  #aaa###",
      "              ##",
      "              a ",
      "              a ",
      "              a ",
      "              ##",
      "               a",
      "               a",
      "              ##",
      "              a ",
      "              a ",
      "              a ",
      "              ##",
      "               a",
      "               a"
    ],
    [
      "###   #aa#   ###",
      "# #aaa#  #aaa###",
      "              ##",
      "              a ",
      "              a ",
      "              a ",
      "              ##",
      "               a",
      "               a",
      "              ##",
      "              a ",
      "              a ",
      "              a ",
      "              ##",
      "               a",
      "               a"
    ]
  ]
}