{
  "xsize": 16,
  "zsize": 16,
  "slices": [
    [
      "QQQQQQQQQQQQQQQQ",
      "QSSQQSSQQSSQQSSQ",
      "QSSQQSSQQSSQQSSQ",
      "QQQSSQQSSQQSSQQQ",
      "QQQSSQQSSQQSSQQQ",
      "QSSQQSSQQSSQQSSQ",
      "QSSQQSSQQSSQQSSQ",
      "QQQSSQQSSQQSSQQQ",
      "QQQSSQQSSQQSSQQQ",
      "QSSQQSSQQSSQQSSQ",
      "QSSQQSSQQSSQQSSQ",
      "QQQSSQQSSQQSSQQQ",
      "QQQSSQQSSQQSSQQQ",
      "QSSQQSSQQSSQQSSQ",
      "QSSQQSSQQSSQQSSQ",
      "QQQSSQQSSQQSSQQQ"
    ],
    [
      "################",
      "#              #",
      "a   C          #",
      "a              #",
      "a              #",
      "a           C  #",
      "a              #",
      "a   C          #",
      "a              #",
      "a              #",
      "a          C   #",
      "a              #",
      "a              #",
      "a              #",
      "a     C        #",
      "a              #"
    ],
    [
      "################",
      "#              #",
      "a              #",
      "a              #",
      "a              #",
      "a              #",
      "a              #",
      "a              #",
      "a              #",
      "a              #",
      "a              #",
      "a              #",
      "a              #",
      "a              #",
      "a              #",
      "a              #"
    ],
    [
      "##aa#aa#aa#aa###",
      "#      T       #",
      "a              #",
      "a              a",
      "a              a",
      "a              #",
      "a              a",
      "a              a",
      "a             T#",
      "a              a",
      "a              a",
      "a              #",
      "a              a",
      "a              a",
      "a              #",
      "a              a"
    ],
    [
      "################",
      "#              #",
      "a              #",
      "a              #",
      "a              #",
      "a              #",
      "a              #",
      "a              #",
      "a              #",
      "a              #",
      "a              #",
      "a              #",
      "a              #",
      "a              #",
      "a              #",
      "a              #"
    ],
    [
      "################",
      "################",
      "################",
      "################",
      "################",
      "################",
      "################",
      "################",
      "################",
      "################",
      "################",
      "################",
      "################",
      "################",
      "################",
      "################"
    ]
  ]
}