{
  "xsize": 16,
  "zsize": 16,
  "slices": [
    [
      "#QQSSQQSSQQSSQQ#",
      "#SSQQSSQQSSQQSS#",
      "#SSQQSSQQSSQQSS#",
      "#QQSSQQSSQQSSQQ#",
      "#QQSSQQSSQQSSQQ#",
      "#SSQQSSQQSSQQSS#",
      "#SSQQSSQQSSQQSS#",
      "#QQSSQQSSQQSSQQ#",
      "#QQSSQQSSQQSSQQ#",
      "#SSQQSSQQSSQQSS#",
      "#SSQQSSQQSSQQSS#",
      "#QQSSQQSSQQSSQQ#",
      "#QQSSQQSSQQSSQQ#",
      "#SSQQSSQQSSQQSS#",
      "#SSQQSSQQSSQQSS#",
      "################"
    ],
    [
      "a              #",
      "a   C          #",
      "a             ##",
      "a          C  # ",
      "a             # ",
      "a             # ",
      "a       C     ##",
      "a              #",
      "a              #",
      "a             ##",
      "a   C         # ",
      "a             # ",
      "a             # ",
      "a          C  ##",
      "a #####  #######",
      "###   ####   ###"
    ],
    [
      "a              a",
      "a              a",
      "a             ##",
      "a             a ",
      "a             a ",
      "a             a ",
      "a            T##",
      "a              a",
      "a              a",
      "a            T##",
      "a             a ",
      "a             a ",
      "a             a ",
      "a     T  T    ##",
      "a #aaa#  #aaa###",
      "###   #aa#   ###"
    ],
    [
      "a              a",
      "a              a",
      "a             ##",
      "a             a ",
      "a             a ",
      "a             a ",
      "a             ##",
      "a              a",
      "a              a",
      "a             ##",
      "a             a ",
      "a             a ",
      "a             a ",
      "a             ##",
      "a #aaa#  #aaa###",
      "###   #aa#   ###"
    ],
    [
      "a              a",
      "a              a",
      "a             ##",
      "a             a ",
      "a             a ",
      "a             a ",
      "a             ##",
      "a              a",
      "a              a",
      "a             ##",
      "a             a ",
      "a             a ",
      "a             a ",
      "a             ##",
      "a #aaa#  #aaa###",
      "###   #aa#   ###"
    ],
    [
      "a              a",
      "a              a",
      "a             ##",
      "a             a ",
      "a             a ",
      "a             a ",
      "a             ##",
      "a              a",
      "a              a",
      "a             ##",
      "a             a ",
      "a             a ",
      "a             a ",
      "a             ##",
      "a #aaa#  #aaa###",
      "###   #aa#   ###"
    ]
  ]
}