{
  "meta": [
    {
      "key": "dontconnect",
      "boolean": true
    }
  ],
  "xsize": 16,
  "zsize": 16,
  "slices": [
    [
      "               a",
      "    C          a",
      "              ##",
      "              a ",
      "              a ",
      "          C   a ",
      "              ##",
      "               a",
      "               a",
      "              ##",
      "      C       a ",
      "              a ",
      "              a ",
      "              ##",
      "  #aaa#  #aaa###",
      "###   #aa#   ###"
    ],
    [
      "               a",
      "               a",
      "              ##",
      "              a ",
      "              a ",
      "              a ",
      "              ##",
      "               a",
      "               a",
      "              ##",
      "              a ",
      "              a ",
      "              a ",
      "              ##",
      "  #aaa#  #aaa###",
      "###   #aa#   ###"
    ],
    [
      "               a",
      "               a",
      "              ##",
      "              a ",
      "              a ",
      "              a ",
      "              ##",
      "               a",
      "               a",
      "              ##",
      "              a ",
      "              a ",
      "              a ",
      "              ##",
      "  #aaa#  #aaa###",
      "###   #aa#   ###"
    ],
    [
      "               a",
      "               a",
      "              ##",
      "              a ",
      "              a ",
      "              a ",
      "              ##",
      "               a",
      "               a",
      "              ##",
      "              a ",
      "              a ",
      "              a ",
      "              ##",
      "  #aaa#  #aaa###",
      "###   #aa#   ###"
    ],
    [
      "               #",
      "               #",
      "              ##",
      "              # ",
      "              # ",
      "              # ",
      "              ##",
      "               #",
      "               #",
      "              ##",
      "              # ",
      "              # ",
      "              # ",
      "              ##",
      "  #####  #######",
      "###   ####   ###"
    ],
    [
      "              ##",
      "              ##",
      "              ##",
      "              ##",
      "              ##",
      "              ##",
      "              ##",
      "              ##",
      "              ##",
      "              ##",
      "              ##",
      "              ##",
      "              ##",
      "              ##",
      "################",
      "################"
    ]
  ]
}