{
  "meta": [
    {
      "key": "dontconnect",
      "boolean": true
    }
  ],
  "xsize": 16,
  "zsize": 16,
  "slices": [
    [
      "################",
      "#SSQQSSQQSSQQSSQ",
      "#SSQQSSQQSSQQSSQ",
      "#QQSSQQSSQQSSQQS",
      "#QQSSQQSSQQSSQQS",
      "#SSQQSSQQSSQQSSQ",
      "#SSQQSSQQSSQQSSQ",
      "#QQSSQQSSQQSSQQS",
      "#QQSSQQSSQQSSQQS",
      "#SSQQSSQQSSQQSSQ",
      "#SSQQSSQQSSQQSSQ",
      "#QQSSQQSSQQSSQQS",
      "#QQSSQQSSQQSSQQS",
      "#SSQQSSQQSSQQSSQ",
      "#SSQQSSQQSSQQSSQ",
      "#QQSSQQSSQQSSQQS"
    ],
    [
      "                ",
      " #  C           ",
      "                ",
      "                ",
      "             C  ",
      "       #))))#   ",
      "   C            ",
      "                ",
      "                ",
      "       w    w   ",
      "             C  ",
      "                ",
      "                ",
      "     C          ",
      "                ",
      "       w    w   "
    ],
    [
      "                ",
      " w              ",
      "                ",
      "                ",
      "                ",
      "       w    w   ",
      "      T#))))#T  ",
      "                ",
      "                ",
      "       w    w   ",
      "                ",
      "                ",
      "                ",
      "                ",
      "                ",
      "       w    w   "
    ],
    [
      "                ",
      " w              ",
      "                ",
      "                ",
      "                ",
      "                ",
      "       w    w   ",
      "       #))))#   ",
      "                ",
      "       w    w   ",
      "                ",
      "                ",
      "                ",
      "                ",
      "                ",
      "       w    w   "
    ],
    [
      "                ",
      " w              ",
      "                ",
      "                ",
      "                ",
      "                ",
      "                ",
      "       w    w   ",
      "       #))))#   ",
      "       w    w   ",
      "                ",
      "                ",
      "                ",
      "                ",
      "                ",
      "       w    w   "
    ],
    [
      "                ",
      " w              ",
      "                ",
      "                ",
      "                ",
      "                ",
      "                ",
      "                ",
      "       w    w   ",
      "       #))))#   ",
      "                ",
      "                ",
      "                ",
      "                ",
      "                ",
      "       w    w   "
    ]
  ]
}