{
  "xsize": 16,
  "zsize": 16,
  "slices": [
    [
      "#QQSSQQSSQQSSQQS",
      "#SSQQSSQQSSQQSSQ",
      "#SSQQSSQQSSQQSSQ",
      "#QQSSQQSSQQSSQQS",
      "#QQSSQQSSQQSSQQS",
      "#SSQQSSQQSSQQSSQ",
      "#SSQQSSQQSSQQSSQ",
      "#QQSSQQSSQQSSQQS",
      "#QQSSQQSSQQSSQQS",
      "#SSQQSSQQSSQQSSQ",
      "#SSQQSSQQSSQQSSQ",
      "#QQSSQQSSQQSSQQS",
      "#QQSSQQSSQQSSQQS",
      "#SSQQSSQQSSQQSSQ",
      "#SSQQSSQQSSQQSSQ",
      "################"
    ],
    [
      "a               ",
      "a    C          ",
      "a               ",
      "a               ",
      "a             C ",
      "a               ",
      "a               ",
      "a   C           ",
      "a               ",
      "a             C ",
      "a               ",
      "a               ",
      "a               ",
      "a       C       ",
      "a               ",
      "aaaaaaaaaaaaaaaa"
    ],
    [
      "a               ",
      "a               ",
      "a               ",
      "a               ",
      "a               ",
      "a               ",
      "a               ",
      "a               ",
      "a               ",
      "a               ",
      "a               ",
      "a               ",
      "a               ",
      "a               ",
      "a               ",
      "aaaaaaaaaaaaaaaa"
    ],
    [
      "a               ",
      "a               ",
      "a               ",
      "a               ",
      "a               ",
      "a               ",
      "a               ",
      "a               ",
      "a               ",
      "a               ",
      "a               ",
      "a               ",
      "a               ",
      "a               ",
      "a               ",
      "aaaaaaaaaaaaaaaa"
    ],
    [
      "a               ",
      "a               ",
      "a               ",
      "a               ",
      "a               ",
      "a               ",
      "a               ",
      "a               ",
      "a               ",
      "a               ",
      "a               ",
      "a               ",
      "a               ",
      "a               ",
      "a               ",
      "aaaaaaaaaaaaaaaa"
    ],
    [
      "a               ",
      "a               ",
      "a               ",
      "a               ",
      "a               ",
      "a               ",
      "a               ",
      "a               ",
      "a               ",
      "a               ",
      "a               ",
      "a               ",
      "a               ",
      "a               ",
      "a               ",
      "aaaaaaaaaaaaaaaa"
    ]
  ]
}