{
  "meta": [
    {
      "key": "dontconnect",
      "boolean": true
    }
  ],
  "xsize": 16,
  "zsize": 16,
  "slices": [
    [
      "###   #aa#   ###",
      "# #aaa#  #aaa###",
      "a             ##",
      "a    C        a ",
      "a             a ",
      "a             a ",
      "a         C   ##",
      "a              a",
      "a              a",
      "a             ##",
      "a    C        a ",
      "a             a ",
      "a             a ",
      "a             ##",
      "a        C     a",
      "a              a"
    ],
    [
      "###   #aa#   ###",
      "# #aaa#  #aaa###",
      "a             ##",
      "a             a ",
      "a             a ",
      "a             a ",
      "a             ##",
      "a              a",
      "a              a",
      "a             ##",
      "a             a ",
      "a             a ",
      "a             a ",
      "a             ##",
      "a              a",
      "a              a"
    ],
    [
      "###   #aa#   ###",
      "# #aaa#  #aaa###",
      "a             ##",
      "a             a ",
      "a             a ",
      "a             a ",
      "a             ##",
      "a              a",
      "a              a",
      "a             ##",
      "a             a ",
      "a             a ",
      "a             a ",
      "a             ##",
      "a              a",
      "a              a"
    ],
    [
      "###   #aa#   ###",
      "# #aaa#  #aaa###",
      "a             ##",
      "a             a ",
      "a             a ",
      "a             a ",
      "a             ##",
      "a              a",
      "a              a",
      "a             ##",
      "a             a ",
      "a             a ",
      "a             a ",
      "a             ##",
      "a              a",
      "a              a"
    ],
    [
      "###   ####   ###",
      "# #####  #######",
      "a             ##",
      "a             # ",
      "a             # ",
      "a             # ",
      "a             ##",
      "a              #",
      "a              #",
      "a             ##",
      "a             # ",
      "a             # ",
      "a             # ",
      "a             ##",
      "a              #",
      "a              #"
    ],
    [
      "################",
      "################",
      "a             ##",
      "a             ##",
      "a             ##",
      "a             ##",
      "a             ##",
      "a             ##",
      "a             ##",
      "a             ##",
      "a             ##",
      "a             ##",
      "a             ##",
      "a             ##",
      "a             ##",
      "a             ##"
    ]
  ]
}