{
  "xsize": 16,
  "zsize": 16,
  "slices": [
    [
      "#QQSSQQSSQQSSQQS",
      "#SSQQSSQQSSQQSSQ",
      "#SSQQSSQQSSQQSSQ",
      "#QQSSQQSSQQSSQQS",
      "#QQSSQQSSQQSSQQS",
      "#SSQQSSQQSSQQSSQ",
      "#SSQQSSQQSSQQSSQ",
      "#QQSSQQSSQQSSQQS",
      "#QQSSQQSSQQSSQQS",
      "#SSQQSSQQSSQQSSQ",
      "#SSQQSSQQSSQQSSQ",
      "#QQSSQQSSQQSSQQS",
      "#QQSSQQSSQQSSQQS",
      "#SSQQSSQQSSQQSSQ",
      "#SSQQSSQQSSQQSSQ",
      "################"
    ],
    [
      "#               ",
      "#   C           ",
      "#               ",
      "#               ",
      "#               ",
      "#           C   ",
      "#               ",
      "#               ",
      "#   C           ",
      "#               ",
      "#               ",
      "#               ",
      "#          C    ",
      "#               ",
      "#               ",
      "################"
    ],
    [
      "#               ",
      "#               ",
      "#               ",
      "#               ",
      "#               ",
      "#               ",
      "#               ",
      "#               ",
      "#               ",
      "#               ",
      "#               ",
      "#               ",
      "#               ",
      "#               ",
      "#               ",
      "################"
    ],
    [
      "a               ",
      "#               ",
      "a               ",
      "a               ",
      "#               ",
      "a               ",
      "a               ",
      "#T              ",
      "a               ",
      "a               ",
      "#               ",
      "a               ",
      "a               ",
      "#               ",
      "#       T       ",
      "###aa#aa#aa#aa#a"
    ],
    [
      "#               ",
      "#               ",
      "#               ",
      "#               ",
      "#               ",
      "#               ",
      "#               ",
      "#               ",
      "#               ",
      "#               ",
      "#               ",
      "#               ",
      "#               ",
      "#               ",
      "#               ",
      "################"
    ],
    [
      "################",
      "################",
      "################",
      "################",
      "################",
      "################",
      "################",
      "################",
      "################",
      "################",
      "################",
      "################",
      "################",
      "################",
      "################",
      "################"
    ]
  ]
}