{
  "xsize": 16,
  "zsize": 16,
  "slices": [
    [
      "################",
      "#SSQQSSQQSSQQSS#",
      "#SSQQSSQQSSQQSS#",
      "#QQSSQQSSQQSSQQ#",
      "#QQSSQQSSQQSSQQ#",
      "#SSQQSSQQSSQQSS#",
      "#SSQQSSQQSSQQSS#",
      "#QQSSQQSSQQSSQQ#",
      "#QQSSQQSSQQSSQQ#",
      "#SSQQSSQQSSQQSS#",
      "#SSQQSSQQSSQQSS#",
      "#QQSSQQSSQQSSQQ#",
      "#QQSSQQSSQQSSQQ#",
      "#SSQQSSQQSSQQSS#",
      "#SSQQSSQQSSQQSS#",
      "#QQSSQQSSQQSSQQ#"
    ],
    [
      "###   ####   ###",
      "# #####  #######",
      "a             ##",
      "a   C         # ",
      "a             # ",
      "a             # ",
      "S          C  ##",
      "               #",
      "    C          #",
      "S             ##",
      "a           C # ",
      "a             # ",
      "a             # ",
      "a             ##",
      "a     C        #",
      "a              #"
    ],
    [
      "###   #aa#   ###",
      "# #aaa#  #aaa###",
      "a     T  T    ##",
      "a             a ",
      "a             a ",
      "a             a ",
      "S            T##",
      "               a",
      "               a",
      "S            T##",
      "a             a ",
      "a             a ",
      "a             a ",
      "a             ##",
      "a              a",
      "a              a"
    ],
    [
      "###   #aa#   ###",
      "# #aaa#  #aaa###",
      "a             ##",
      "a             a ",
      "a             a ",
      "a             a ",
      "S             ##",
      "S              a",
      "S              a",
      "S             ##",
      "a             a ",
      "a             a ",
      "a             a ",
      "a             ##",
      "a              a",
      "a              a"
    ],
    [
      "###   #aa#   ###",
      "# #aaa#  #aaa###",
      "a             ##",
      "a             a ",
      "a             a ",
      "a             a ",
      "a             ##",
      "a              a",
      "a              a",
      "a             ##",
      "a             a ",
      "a             a ",
      "a             a ",
      "a             ##",
      "a              a",
      "a              a"
    ],
    [
      "###   #aa#   ###",
      "# #aaa#  #aaa###",
      "a             ##",
      "a             a ",
      "a             a ",
      "a             a ",
      "a             ##",
      "a              a",
      "a              a",
      "a             ##",
      "a             a ",
      "a             a ",
      "a             a ",
      "a             ##",
      "a              a",
      "a              a"
    ]
  ]
}