{
  "xsize": 16,
  "zsize": 16,
  "slices": [
    [
      "##::#aaaaaa#::##",
      "#####SQSQSQ#####",
      ":#SQSQSQSQSQSQSQ",
      ":#QSQSQSQSQSQSQS",
      "##SQSQSQSQSQSQSQ",
      "aSQSQSQSQSQSQSQS",
      "aQSQSQSQSQSQSQSQ",
      "aSQSQSQSQSQSQSQS",
      "aQSQSQSQSQSQSQSQ",
      "aSQSQSQSQSQSQSQS",
      "aQSQSQSQSQSQS  Q",
      "##QSQSQSQSQSQ  S",
      ":#SQSQSQSQSQS  Q",
      ":#QSQSQSQSQSQ  S",
      "##SQSQSQSQSQS))Q",
      "##QSQSQSQSQSQSQS"
    ],
    [
      "##::#aaaaaa#::##",
      "##aa#      #aa##",
      ":a   C          ",
      ":a              ",
      "##            C ",
      "a               ",
      "a               ",
      "a    C          ",
      "a               ",
      "a            )) ",
      "a           Q  Q",
      "##          Q  Q",
      ":a          Q  Q",
      ":a    C     Q  Q",
      "##          Q  Q",
      "##              "
    ],
    [
      "##::#aaaaaa#::##",
      "##aa#      #aa##",
      ":a              ",
      ":a              ",
      "##              ",
      "a               ",
      "a               ",
      "a               ",
      "a               ",
      "a               ",
      "a           a))a",
      "##          a  a",
      ":a          a  a",
      ":a          a  a",
      "##          a  a",
      "##              "
    ],
    [
      "##::#aaaaaa#::##",
      "##aa#      #aa##",
      ":a              ",
      ":a              ",
      "##              ",
      "a               ",
      "a               ",
      "a               ",
      "a               ",
      "a               ",
      "a           a  a",
      "##          a))a",
      ":a          a  a",
      ":a          a  a",
      "##          a  a",
      "##              "
    ],
    [
      "##::#aaaaaa#::##",
      "##aa#      #aa##",
      ":a              ",
      ":a              ",
      "##              ",
      "a               ",
      "a               ",
      "a               ",
      "a               ",
      "a               ",
      "a           a  a",
      "##          a  a",
      ":a          a))a",
      ":a          a  a",
      "##          a  a",
      "##              "
    ],
    [
      "##::#aaaaaa#::##",
      "################",
      ":###############",
      ":###############",
      "################",
      "a###############",
      "a###############",
      "a###############",
      "a###############",
      "a###############",
      "a############  #",
      "#############  #",
      ":############  #",
      ":############))#",
      "#############  #",
      "################"
    ]
  ]
}