{
  "xsize": 16,
  "zsize": 16,
  "slices": [
    [
      "SQSQSQSQSQSQSQ##",
      "QSQSQSQSQSQSQSQ#",
      "SQSQSQSQSQSQSQS#",
      "QSQSQSQSQSQSQSQ#",
      "SQSQSQSQSQSQSQS#",
      "QSQSQSQSQSQSQSQ#",
      "SQSQSQSQSQSQSQS#",
      "QSQSQSQSQSQSQSQ#",
      "SQSQSQSQSQSQSQS#",
      "QSQSQSQSQSQSQSQ#",
      "SQSQSQSQSQSQSQS#",
      "QSQSQSQSQSQSQSQ#",
      "SQSQSQSQSQSQSQS#",
      "QSQSQSQSQSQSQSQ#",
      "#QSQSQSQSQSQSQ##",
      "################"
    ],
    [
      "              ##",
      "   C           a",
      "               a",
      "               a",
      "               a",
      "             C a",
      "               a",
      "    C          a",
      "               a",
      "               a",
      "               a",
      "               a",
      "       C       a",
      "               a",
      "#             ##",
      "#aaaaaaaaaaaaa##"
    ],
    [
      "              ##",
      "               a",
      "               a",
      "               a",
      "               a",
      "               a",
      "               a",
      "               a",
      "               a",
      "               a",
      "               a",
      "               a",
      "               a",
      "               a",
      "#             ##",
      "#aaaaaaaaaaaaa##"
    ],
    [
      "              ##",
      "               a",
      "               a",
      "               a",
      "               a",
      "               a",
      "               a",
      "               a",
      "               a",
      "               a",
      "               a",
      "               a",
      "               a",
      "               a",
      "#             ##",
      "#aaaaaaaaaaaaa##"
    ],
    [
      "              ##",
      "               a",
      "               a",
      "               a",
      "               a",
      "               a",
      "               a",
      "               a",
      "               a",
      "               a",
      "               a",
      "               a",
      "               a",
      "               a",
      "#             ##",
      "#aaaaaaaaaaaa:##"
    ],
    [
      "################",
      "################",
      "################",
      "################",
      "################",
      "################",
      "################",
      "################",
      "################",
      "################",
      "################",
      "################",
      "################",
      "################",
      "################",
      "################"
    ]
  ]
}