{
  "xsize": 16,
  "zsize": 16,
  "slices": [
    [
      "################",
      "##QSQSQSQSQSQSQ#",
      "#QSQSQSQSQSQSQSQ",
      "#SQSQSQSQSQSQSQS",
      "#QSQSQSQSQSQSQSQ",
      "#SQSQSQSQSQSQSQS",
      "#QSQSQSQSQSQSQSQ",
      "#SQSQSQSQSQSQSQS",
      "#QSQSQSQSQSQSQSQ",
      "#SQSQSQSQSQSQSQS",
      "#QSQSQSQSQSQS  Q",
      "#SQSQSQSQSQSQ  S",
      "#QSQSQSQSQSQS  Q",
      "#SQSQSQSQSQSQ  S",
      "#QSQSQSQSQSQS))Q",
      "##QSQSQSQSQSQSQS"
    ],
    [
      "##::#########::#",
      "##        C    #",
      ":               ",
      ":               ",
      "#  C            ",
      "#               ",
      "#            C  ",
      "#               ",
      "#               ",
      "#            )) ",
      "#   C       Q  Q",
      "#           Q  Q",
      "#           Q  Q",
      ":           Q  Q",
      ":      C    Q  Q",
      "##              "
    ],
    [
      "##::#########::#",
      "##             #",
      ":               ",
      ":               ",
      "#               ",
      "#               ",
      "#               ",
      "#               ",
      "#               ",
      "#               ",
      "#           a))a",
      "#           a  a",
      "#           a  a",
      ":           a  a",
      ":           a  a",
      "##              "
    ],
    [
      "##::#########::#",
      "##             #",
      ":               ",
      ":               ",
      "#               ",
      "#               ",
      "#               ",
      "#               ",
      "#               ",
      "#               ",
      "#           a  a",
      "#           a))a",
      "#           a  a",
      ":           a  a",
      ":           a  a",
      "##              "
    ],
    [
      "##::#########::#",
      "##             #",
      ":               ",
      ":               ",
      "#               ",
      "#               ",
      "#               ",
      "#               ",
      "#               ",
      "#               ",
      "#           a  a",
      "#           a  a",
      "#           a))a",
      ":           a  a",
      ":           a  a",
      "##              "
    ],
    [
      "################",
      "################",
      "################",
      "################",
      "################",
      "################",
      "################",
      "################",
      "################",
      "################",
      "#############  #",
      "#############  #",
      "#############  #",
      "#############))#",
      "#############  #",
      "################"
    ]
  ]
}