{
  "xsize": 16,
  "zsize": 16,
  "slices": [
    [
      "##::#aaaaaa#::##",
      "#####SQSQSQ#####",
      "SQSQSQSQSQSQSQ#:",
      "QSQSQSQSQSQSQS#:",
      "SQSQSQSQSQSQSQ##",
      "QSQSQSQSQSQSQSQa",
      "SQSQSQSQSQSQSQSa",
      "QSQSQSQSQSQSQSQa",
      "SQSQSQSQSQSQSQSa",
      "QSQSQSQSQSQSQSQa",
      "SQSQSQSQSQSQSQSa",
      "QSQSQSQSQSQSQS##",
      "SQSQSQSQSQSQSQ#:",
      "QSQSQSQSQSQSQS#:",
      "SQSQSQSQSQSQSQ##",
      "QSQSQSQSQSQSQS##"
    ],
    [
      "##::#aaaaaa#::##",
      "##aa#      #aa##",
      "        C     a:",
      "              a:",
      "              ##",
      "               a",
      "   C           a",
      "               a",
      "               a",
      "            C  a",
      "               a",
      "              ##",
      "   C          a:",
      "              a:",
      "              ##",
      "          C   ##"
    ],
    [
      "##::#aaaaaa#::##",
      "##aa#      #aa##",
      "              a:",
      "              a:",
      "              ##",
      "               a",
      "               a",
      "               a",
      "               a",
      "               a",
      "               a",
      "              ##",
      "              a:",
      "              a:",
      "              ##",
      "              ##"
    ],
    [
      "##::#aaaaaa#::##",
      "##aa#      #aa##",
      "              a:",
      "              a:",
      "              ##",
      "               a",
      "               a",
      "               a",
      "               a",
      "               a",
      "               a",
      "              ##",
      "              a:",
      "              a:",
      "              ##",
      "              ##"
    ],
    [
      "##::#aaaaaa#::##",
      "##aa#      #aa##",
      "              a:",
      "              a:",
      "              ##",
      "               a",
      "               a",
      "               a",
      "               a",
      "               a",
      "               a",
      "              ##",
      "              a:",
      "              a:",
      "              ##",
      "              ##"
    ],
    [
      "##::#aaaaaa#::##",
      "################",
      "###############:",
      "###############:",
      "################",
      "###############a",
      "###############a",
      "###############a",
      "###############a",
      "###############a",
      "###############a",
      "################",
      "###############:",
      "###############:",
      "################",
      "################"
    ]
  ]
}