{
  "xsize": 16,
  "zsize": 16,
  "slices": [
    [
      "SQSQSQSQSQSQSQ##",
      "QSQSQSQSQSQSQS##",
      "SQSQSQSQSQSQSQ#:",
      "QSQSQSQSQSQSQS#:",
      "SQSQSQSQSQSQSQ##",
      "QSQSQSQSQSQSQSQa",
      "SQSQSQSQSQSQSQSa",
      "QSQSQSQSQSQSQSQa",
      "SQSQSQSQSQSQSQSa",
      "QSQSQSQSQSQSQSQa",
      "SQSQSQSQSQSQSQSa",
      "QSQSQSQSQSQSQS##",
      "SQSQSQSQSQSQSQ#:",
      "QSQSQSQSQSQSQS#:",
      "#####QSQSQS#####",
      "##::#aaaaaa#::##"
    ],
    [
      "              ##",
      "   C          ##",
      "              a:",
      "              a:",
      "              ##",
      "           C   a",
      "               a",
      "               a",
      "  C            a",
      "            C  a",
      "               a",
      "              ##",
      "              a:",
      "      C       a:",
      "##aa#      #aa##",
      "##::#aaaaaa#::##"
    ],
    [
      "              ##",
      "              ##",
      "              a:",
      "              a:",
      "              ##",
      "               a",
      "               a",
      "               a",
      "               a",
      "               a",
      "               a",
      "              ##",
      "              a:",
      "              a:",
      "##aa#      #aa##",
      "##::#aaaaaa#::##"
    ],
    [
      "              ##",
      "              ##",
      "              a:",
      "              a:",
      "              ##",
      "               a",
      "               a",
      "               a",
      "               a",
      "               a",
      "               a",
      "              ##",
      "              a:",
      "              a:",
      "##aa#      #aa##",
      "##::#aaaaaa#::##"
    ],
    [
      "              ##",
      "              ##",
      "              a:",
      "              a:",
      "              ##",
      "               a",
      "               a",
      "               a",
      "               a",
      "               a",
      "               a",
      "              ##",
      "              a:",
      "              a:",
      "##aa#      #aa##",
      "##::#aaaaaa#::##"
    ],
    [
      "################",
      "################",
      "###############:",
      "###############:",
      "################",
      "###############a",
      "###############a",
      "###############a",
      "###############a",
      "###############a",
      "###############a",
      "################",
      "###############:",
      "###############:",
      "################",
      "##::#aaaaaa#::##"
    ]
  ]
}