{
  "xsize": 16,
  "zsize": 16,
  "slices": [
    [
      "################",
      "#SQSQSQSQSQSQS##",
      "SQSQSQSQSQSQSQS#",
      "QSQSQSQSQSQSQSQ#",
      "SQSQSQSQSQSQSQS#",
      "QSQSQSQSQSQSQSQ#",
      "SQSQSQSQSQSQSQS#",
      "QSQSQSQSQSQSQSQ#",
      "SQSQSQSQSQSQSQS#",
      "QSQSQSQSQSQSQSQ#",
      "SQSQSQSQSQSQSQS#",
      "QSQSQSQSQSQSQSQ#",
      "SQSQSQSQSQSQSQS#",
      "QSQSQSQSQSQSQSQ#",
      "SQSQSQSQSQSQSQS#",
      "QSQSQSQSQSQSQS##"
    ],
    [
      "#::#########::##",
      "#             ##",
      "      C        :",
      "               :",
      "               #",
      "               #",
      "             C #",
      "               #",
      "   C           #",
      "               #",
      "               #",
      "               #",
      "               #",
      "        C      :",
      "               :",
      "              ##"
    ],
    [
      "#::#########::##",
      "#             ##",
      "               :",
      "               :",
      "               #",
      "               #",
      "               #",
      "               #",
      "               #",
      "               #",
      "               #",
      "               #",
      "               #",
      "               :",
      "               :",
      "              ##"
    ],
    [
      "#::#########::##",
      "#             ##",
      "               :",
      "               :",
      "               #",
      "               #",
      "               #",
      "               #",
      "               #",
      "               #",
      "               #",
      "               #",
      "               #",
      "               :",
      "               :",
      "              ##"
    ],
    [
      "#::#########::##",
      "#             ##",
      "               :",
      "               :",
      "               #",
      "               #",
      "               #",
      "               #",
      "               #",
      "               #",
      "               #",
      "               #",
      "               #",
      "               :",
      "               :",
      "              ##"
    ],
    [
      "################",
      "################",
      "################",
      "################",
      "################",
      "################",
      "################",
      "################",
      "################",
      "################",
      "################",
      "################",
      "################",
      "################",
      "################",
      "################"
    ]
  ]
}