{
  "xsize": 16,
  "zsize": 16,
  "slices": [
    [
      "SQSQSQSQSQSQSQ##",
      "QSQSQSQSQSQSQSQ#",
      "SQSQSQSQSQSQSQS#",
      "QSQSQSQSQSQSQSQ#",
      "SQSQSQSQSQSQSQS#",
      "QSQSQSQSQSQSQSQ#",
      "SQSQSQSQSQSQSQS#",
      "QSQSQSQSQSQSQSQ#",
      "SQSQSQSQSQSQSQS#",
      "QSQSQSQSQSQSQSQ#",
      "SQSQSQSQSQSQSQS#",
      "QSQSQSQSQSQSQSQ#",
      "SQSQSQSQSQSQSQS#",
      "QSQSQSQSQSQSQSQ#",
      "#QSQSQSQSQSQSQ##",
      "################"
    ],
    [
      "              ##",
      "   C           :",
      "               :",
      "               #",
      "               #",
      "            C  #",
      "               #",
      "               #",
      "   C           #",
      "               #",
      "               #",
      "               #",
      "         C     :",
      "               :",
      "#             ##",
      "#::#########::##"
    ],
    [
      "              ##",
      "               :",
      "               :",
      "               #",
      "               #",
      "               #",
      "               #",
      "               #",
      "               #",
      "               #",
      "               #",
      "               #",
      "               :",
      "               :",
      "#             ##",
      "#::#########::##"
    ],
    [
      "              ##",
      "               :",
      "               :",
      "               #",
      "               #",
      "               #",
      "               #",
      "               #",
      "               #",
      "               #",
      "               #",
      "               #",
      "               :",
      "               :",
      "#             ##",
      "#::#########::##"
    ],
    [
      "              ##",
      "               :",
      "               :",
      "               #",
      "               #",
      "               #",
      "               #",
      "               #",
      "               #",
      "               #",
      "               #",
      "               #",
      "               :",
      "               :",
      "#             ##",
      "#::#########::##"
    ],
    [
      "################",
      "################",
      "################",
      "################",
      "################",
      "################",
      "################",
      "################",
      "################",
      "################",
      "################",
      "################",
      "################",
      "################",
      "################",
      "################"
    ]
  ]
}