{
  "xsize": 16,
  "zsize": 16,
  "slices": [
    [
      "##SQSQSQSQSQSQSQ",
      "#SQSQSQSQSQSQSQS",
      "#QSQSQSQSQSQSQSQ",
      "#SQSQSQSQSQSQSQS",
      "#QSQSQSQSQSQSQSQ",
      "#SQSQSQSQSQSQSQS",
      "#QSQSQSQSQSQSQSQ",
      "#SQSQSQSQSQSQSQS",
      "#QSQSQSQSQSQSQSQ",
      "#SQSQSQSQSQSQSQS",
      "#QSQSQSQSQSQSQSQ",
      "#SQSQSQSQSQSQSQS",
      "#QSQSQSQSQSQSQSQ",
      "#SQSQSQSQSQSQSQS",
      "##SQSQSQSQSQSQS#",
      "################"
    ],
    [
      "##              ",
      ":    C          ",
      ":               ",
      "#               ",
      "#            C  ",
      "#               ",
      "#               ",
      "#  C    T       ",
      "#               ",
      "#               ",
      "#            C  ",
      "#               ",
      ":     C         ",
      ":               ",
      "##             #",
      "##::#########::#"
    ],
    [
      "##              ",
      ":               ",
      ":               ",
      "#               ",
      "#               ",
      "#               ",
      "#               ",
      "#               ",
      "#               ",
      "#               ",
      "#               ",
      "#               ",
      ":               ",
      ":               ",
      "##             #",
      "##::#########::#"
    ],
    [
      "##              ",
      ":               ",
      ":               ",
      "#               ",
      "#               ",
      "#               ",
      "#               ",
      "#               ",
      "#               ",
      "#               ",
      "#               ",
      "#               ",
      ":               ",
      ":               ",
      "##             #",
      "##::#########::#"
    ],
    [
      "##              ",
      ":               ",
      ":               ",
      "#               ",
      "#               ",
      "#               ",
      "#               ",
      "#               ",
      "#               ",
      "#               ",
      "#               ",
      "#               ",
      ":               ",
      ":               ",
      "##             #",
      "##::#########::#"
    ],
    [
      "################",
      "################",
      "################",
      "################",
      "################",
      "################",
      "################",
      "################",
      "################",
      "################",
      "################",
      "################",
      "################",
      "################",
      "################",
      "################"
    ]
  ]
}