{
  "xsize": 16,
  "zsize": 16,
  "slices": [
    [
      "                ",
      "                ",
      "                ",
      "                ",
      "                ",
      "                ",
      "                ",
      "                ",
      "                ",
      "                ",
      "                ",
      "                ",
      "                ",
      "                ",
      "                ",
      "                "
    ],
    [
      "                ",
      "  C             ",
      "   ##########   ",
      "   #        #   ",
      "   #  C     #   ",
      "   #  ##### #   ",
      "   #  #     #   ",
      "   #  # ### #C  ",
      "   #  # #   #   ",
      "   #  # # C #   ",
      "   # 4# #4  #   ",
      "   #### #####   ",
      "                ",
      "                ",
      "       C        ",
      "                "
    ],
    [
      "                ",
      "                ",
      "   ##########   ",
      "   #        #   ",
      "   #        #   ",
      "   #  ##### #   ",
      "   #  #     #   ",
      "   #  # ### #   ",
      "   #  # #   #   ",
      "   #  # #   #   ",
      "   #  # #   #   ",
      "   #### #####   ",
      "                ",
      "                ",
      "                ",
      "                "
    ],
    [
      "                ",
      "                ",
      "   ##########   ",
      "   #        #   ",
      "   #        #   ",
      "   #  ##### #   ",
      "   #  #     #   ",
      "   #  # ### #   ",
      "   #  # #   #   ",
      "   #  # #   #   ",
      "   #  # #   #   ",
      "   ##########   ",
      "                ",
      "                ",
      "                ",
      "                "
    ],
    [
      "                ",
      "                ",
      "   ##########   ",
      "   #        #   ",
      "   #        #   ",
      "   #  ##### #   ",
      "   #  #     #   ",
      "   #  # ### #   ",
      "   #  # #   #   ",
      "   #  # #   #   ",
      "   #  # #   #   ",
      "   ##########   ",
      "                ",
      "                ",
      "                ",
      "                "
    ]
  ]
}