{
  "xsize": 16,
  "zsize": 16,
  "slices": [
    [
      "##SQSQSQSQSQSQSQ",
      "#SQSQSQSQSQSQSQS",
      "#QSQSQSQSQSQSQSQ",
      "#SQSQSQSQSQSQSQS",
      "#QSQSQSQSQSQSQSQ",
      "#SQSQSQSQSQSQSQS",
      "#QSQSQSQSQSQSQSQ",
      "#SQSQSQSQSQSQSQS",
      "#QSQSQSQSQSQSQSQ",
      "#SQSQSQSQSQSQSQS",
      "#QSQSQSQSQSQSQSQ",
      "#SQSQSQSQSQSQSQS",
      "#QSQSQSQSQSQSQSQ",
      "#SQSQSQSQSQSQSQS",
      "##SQSQSQSQSQSQS#",
      "################"
    ],
    [
      "##              ",
      "a    C          ",
      "a               ",
      "a             C ",
      "a               ",
      "a   C           ",
      "a               ",
      "a       T       ",
      "a               ",
      "a            C  ",
      "a               ",
      "a               ",
      "a   C           ",
      "a               ",
      "##             #",
      "##aaaaaaaaaaaaa#"
    ],
    [
      "##              ",
      "a               ",
      "a               ",
      "a               ",
      "a               ",
      "a               ",
      "a               ",
      "a               ",
      "a               ",
      "a               ",
      "a               ",
      "a               ",
      "a               ",
      "a               ",
      "##             #",
      "##aaaaaaaaaaaaa#"
    ],
    [
      "##              ",
      "a               ",
      "a               ",
      "a               ",
      "a               ",
      "a               ",
      "a               ",
      "a               ",
      "a               ",
      "a               ",
      "a               ",
      "a               ",
      "a               ",
      "a               ",
      "##             #",
      "##aaaaaaaaaaaaa#"
    ],
    [
      "##              ",
      "a               ",
      "a               ",
      "a               ",
      "a               ",
      "a               ",
      "a               ",
      "a               ",
      "a               ",
      "a               ",
      "a               ",
      "a               ",
      "a               ",
      "a               ",
      "##             #",
      "##aaaaaaaaaaaaa#"
    ],
    [
      "################",
      "################",
      "################",
      "################",
      "################",
      "################",
      "################",
      "################",
      "################",
      "################",
      "################",
      "################",
      "################",
      "################",
      "################",
      "################"
    ]
  ]
}