{
  "xsize": 16,
  "zsize": 16,
  "slices": [
    [
      "                ",
      "                ",
      "                ",
      "                ",
      "                ",
      "                ",
      "                ",
      "                ",
      "                ",
      "                ",
      "                ",
      "                ",
      "                ",
      "                ",
      "                ",
      "                "
    ],
    [
      "                ",
      "   C            ",
      "                ",
      "   ##########   ",
      "   #4      4# C ",
      "   #    !!  #   ",
      "   #  ##### #   ",
      "   # !#     #   ",
      "   # !# ### #   ",
      "   #  # #4  #   ",
      "   #  # #   #   ",
      "   # 4# #C  #   ",
      "   #### #####   ",
      "                ",
      "        C       ",
      "                "
    ],
    [
      "                ",
      "                ",
      "                ",
      "   ##########   ",
      "   #        #   ",
      "   #        #   ",
      "   #  ##### #   ",
      "   #  #     #   ",
      "   #  # ### #   ",
      "   #  # #   #   ",
      "   #  # #   #   ",
      "   #  # #   #   ",
      "   #### #####   ",
      "                ",
      "                ",
      "                "
    ],
    [
      "                ",
      "                ",
      "                ",
      "   ##########   ",
      "   #        #   ",
      "   #        #   ",
      "   #  ##### #   ",
      "   #  #     #   ",
      "   #  # ### #   ",
      "   #  # #   #   ",
      "   #  # #   #   ",
      "   #  # #   #   ",
      "   ##########   ",
      "                ",
      "                ",
      "                "
    ],
    [
      "                ",
      "                ",
      "                ",
      "   ##########   ",
      "   #        #   ",
      "   #        #   ",
      "   #  ##### #   ",
      "   #  #     #   ",
      "   #  # ### #   ",
      "   #  # #   #   ",
      "   #  # #   #   ",
      "   #  # #   #   ",
      "   ##########   ",
      "                ",
      "                ",
      "                "
    ]
  ]
}