{
  "xsize": 16,
  "zsize": 16,
  "slices": [
    [
      "##SQSQSQSQSQSQSQ",
      "##QSQSQSQSQSQSQS",
      ":#SQSQSQSQSQSQSQ",
      ":#QSQSQSQSQSQSQS",
      "##SQSQSQSQSQSQSQ",
      "aSQSQSQSQSQSQSQS",
      "aQSQSQSQSQSQSQSQ",
      "aSQSQSQSQSQSQSQS",
      "aQSQSQSQSQSQSQSQ",
      "aSQSQSQSQSQSQSQS",
      "aQSQSQSQSQSQSQSQ",
      "##QSQSQSQSQSQSQS",
      ":#SQSQSQSQSQSQSQ",
      ":#QSQSQSQSQSQSQS",
      "#####QSQSQS#####",
      "##::#aaaaaa#::##"
    ],
    [
      "##              ",
      "##   C          ",
      ":a              ",
      ":a            C ",
      "##              ",
      "a  C            ",
      "a               ",
      "a       T       ",
      "a               ",
      "a            C  ",
      "a               ",
      "##   C          ",
      ":a              ",
      ":a              ",
      "##aa#      #aa##",
      "##::#aaaaaa#::##"
    ],
    [
      "##              ",
      "##              ",
      ":a              ",
      ":a              ",
      "##              ",
      "a               ",
      "a               ",
      "a               ",
      "a               ",
      "a               ",
      "a               ",
      "##              ",
      ":a              ",
      ":a              ",
      "##aa#      #aa##",
      "##::#aaaaaa#::##"
    ],
    [
      "##              ",
      "##              ",
      ":a              ",
      ":a              ",
      "##              ",
      "a               ",
      "a               ",
      "a               ",
      "a               ",
      "a               ",
      "a               ",
      "##              ",
      ":a              ",
      ":a              ",
      "##aa#      #aa##",
      "##::#aaaaaa#::##"
    ],
    [
      "##              ",
      "##              ",
      ":a              ",
      ":a              ",
      "##              ",
      "a               ",
      "a               ",
      "a               ",
      "a               ",
      "a               ",
      "a               ",
      "##              ",
      ":a              ",
      ":a              ",
      "##aa#      #aa##",
      "##::#aaaaaa#::##"
    ],
    [
      "################",
      "################",
      ":###############",
      ":###############",
      "################",
      "a###############",
      "a###############",
      "a###############",
      "a###############",
      "a###############",
      "a###############",
      "################",
      ":###############",
      ":###############",
      "################",
      "##::#aaaaaa#::##"
    ]
  ]
}