{
  "xsize": 16,
  "zsize": 16,
  "slices": [
    [
      "################",
      "##QSQSQSQSQSQSQ#",
      "#QSQSQSQSQSQSQSQ",
      "#SQSQSQSQSQSQSQS",
      "#QSQSQSQSQSQSQSQ",
      "#SQSQSQSQSQSQSQS",
      "#QSQSQSQSQSQSQSQ",
      "#SQSQSQSQSQSQSQS",
      "#QSQSQSQSQSQSQSQ",
      "#SQSQSQSQSQSQSQS",
      "#QSQSQSQSQSQS  Q",
      "#SQSQSQSQSQSQ  S",
      "#QSQSQSQSQSQS  Q",
      "#SQSQSQSQSQSQ  S",
      "#QSQSQSQSQSQS))Q",
      "##QSQSQSQSQSQSQS"
    ],
    [
      "##aaaaaaaaaaaaa#",
      "##             #",
      "a   C           ",
      "a               ",
      "a            C  ",
      "a               ",
      "a               ",
      "a      C        ",
      "a               ",
      "a            )) ",
      "a   C       Q  Q",
      "a           Q  Q",
      "a           Q  Q",
      "a           Q  Q",
      "a        C  Q  Q",
      "##              "
    ],
    [
      "##aaaaaaaaaaaaa#",
      "##             #",
      "a               ",
      "a               ",
      "a               ",
      "a               ",
      "a               ",
      "a               ",
      "a               ",
      "a               ",
      "a           a))a",
      "a           a  a",
      "a           a  a",
      "a           a  a",
      "a           a  a",
      "##              "
    ],
    [
      "##aaaaaaaaaaaaa#",
      "##             #",
      "a               ",
      "a               ",
      "a               ",
      "a               ",
      "a               ",
      "a               ",
      "a               ",
      "a               ",
      "a           a  a",
      "a           a))a",
      "a           a  a",
      "a           a  a",
      "a           a  a",
      "##              "
    ],
    [
      "##aaaaaaaaaaaaa#",
      "##             #",
      "a               ",
      "a               ",
      "a               ",
      "a               ",
      "a               ",
      "a               ",
      "a               ",
      "a               ",
      "a           a  a",
      "a           a  a",
      "a           a))a",
      "a           a  a",
      "a           a  a",
      "##              "
    ],
    [
      "################",
      "################",
      "################",
      "################",
      "################",
      "################",
      "################",
      "################",
      "################",
      "################",
      "#############  #",
      "#############  #",
      "#############  #",
      "#############))#",
      "#############  #",
      "################"
    ]
  ]
}